Workbook

Sheet RELAWAN
B2: PEMERINTAH KOTA BANJARBARU
B3: SATUAN POLISI PAMONG PRAJA
B4: Alamat : Jl. Pangeran Antasari No. 7 Banjarbaru Kalimantan Selatan
B5: Website : Satpolpp.banjarbarukota.go.id – Email : admin@satpolpp.banjarbarukota.go.id
B7: RELAWAN KEBAKARAN
B8: BINAAN UPT PEMADAM KEBAKARAN DAN PENYELAMATAN
B9: KOTA BANJARBARU
B11: NO | C11: NIK | D11: NAMA
B12: 1 | C12: 63************01 | D12: BADRIANOR
B13: 2 | C13: 63************01 | D13: HAFIF ANSARI
B14: 3 | C14: 63************05 | D14: NUR IFANSYAH
B15: 4 | C15: 63************08 | D15: MUHAMMAD SOLEHIN
B16: 5 | C16: 63************01 | D16: M.SURYA
B17: 6 | C17: 63************04 | D17: ANNISA FITRIANY
B18: 7 | C18: 63************03 | D18: HENDRI WIJAYA PUTRA
B19: 8 | C19: 63************01 | D19: ZAINUDIN
B20: 9 | C20: 63************06 | D20: RUSDIANNOOR
B21: 10 | C21: 63************02 | D21: SUWANTO
B22: 11 | C22: 63************04 | D22: H.M.MAKKI
B23: 12 | C23: 63************02 | D23: AHMAD MUZAKIR
... B275: 264 | C275: 63************05 | D275: ROLIA EVA SAFITRI
D277: Banjarbaru, Januari 2026
D278: Kepala Satuan Polisi Pamong Praja
D282: DEDY SUTOYO, SSTP, MM.
D283: Pembina Utama Muda
D284: NIP. 19771127 199612 1 001

Sheet APARATUR
B1: PEMERINTAH KOTA BANJARBARU
B2: SATUAN POLISI PAMONG PRAJA
B3: Alamat : Jl. Pangeran Antasari No. 7 Banjarbaru Kalimantan Selatan
C4: Website : Satpolpp.banjarbarukota.go.id – Email : admin@satpolpp.banjarbarukota.go.id
A6: APARATUR PEMADAM KEBAKARAN YANG MEMENUHI STANDAR KUALIFIKASI PEMADAM
A7: PERATURAN MENTERI DALAM NEGERI NO. 16 TAHUN 2009 TENTANG STANDAR KUALIFIKASI APARATUR PEMADAM KEBAKARAN
B8: UPT PEMADAM KEBAKARAN DAN PENYELAMATAN KOTA BANJARBARU
B10: NO | C10: NAMA | G10: SERTIFIKAT KOMPETENSI | J10: TANDA TANGAN SERTIFIKAT | M10: NO REGISTRASI | Q10: TAHUN DIKLAT
B11: 1 | C11: SYAFRULLAH, S.Sos, M.Si. | G11: PEMADAM 1 | J11: DITJEN BINA ADWIL KEMENDAGRI | M11: P.157/116/TU/DAMKAR/MPBK/2024 | Q11: 2024
B12: 2 | C12: ADE SUSANTO | G12: PEMADAM 1 | J12: DITJEN BINA ADWIL KEMENDAGRI | M12: P.3/578/TU/SDV/MPBK/2022 | Q12: 2022
B13: 3 | C13: RANU WIBOWO | G13: PEMADAM 1 | J13: DITJEN BINA ADWIL KEMENDAGRI | M13: P.25/240/TU/SDV/MPBK/2022 | Q13: 2022
B14: 4 | C14: IMAM KASTALANI | G14: PEMADAM 1 | J14: DITJEN BINA ADWIL KEMENDAGRI | M14: P.22/238/TU/DAMKAR/MPBK/2024 | Q14: 2024
B15: 5 | C15: AGUS BUDIANTO | G15: PEMADAM 1 | J15: DITJEN BINA ADWIL KEMENDAGRI | M15: P.77/238/TU/DAMKAR/MPBK/2024 | Q15: 2024
B16: 6 | C16: BUDI ADI | G16: PEMADAM 1 | J16: DITJEN BINA ADWIL KEMENDAGRI | M16: P.82/238/TU/DAMKAR/MPBK/2024 | Q16: 2024
B17: 7 | C17: MUHAMMAD NOOR | G17: PEMADAM 1 | J17: DITJEN BINA ADWIL KEMENDAGRI | M17: P.19/141 /TU/DAMKAR/MPBK/2025 | Q17: 2025
B18: 8 | C18: MUHAMMAD FIKRI NISFUADI | G18: PEMADAM 1 | J18: DITJEN BINA ADWIL KEMENDAGRI | M18: P.52/141 /TU/DAMKAR/MPBK/2025 | Q18: 2025
K20: Banjarbaru, Januari 2026
K21: Kepala Satuan Polisi Pamong Praja
K25: DEDY SUTOYO, SSTP, MM.
K26: Pembina Utama Muda
K27: NIP. 19771127 199612 1 001

Sheet JUMLAH KAPASITAS
B1: PEMERINTAH KOTA BANJARBARU
B2: SATUAN POLISI PAMONG PRAJA
B3: Alamat : Jl. Pangeran Antasari No. 7 Banjarbaru Kalimantan Selatan
C4: Website : Satpolpp.banjarbarukota.go.id – Email : admin@satpolpp.banjarbarukota.go.id
A6: JUMLAH PENINGKATAN KAPASITAS APARATUR PEMADAM KEBAKARAN
B9: NO | C9: NAMA | G9: SERTIFIKAT KOMPETENSI | J9: TANDA TANGAN SERTIFIKAT | M9: NO REGISTRASI | Q9: TAHUN DIKLAT
B10: 1 | C10: SYAFRULLAH, S.Sos, M.Si. | G10: PEMADAM 1 | J10: DITJEN BINA ADWIL KEMENDAGRI | M10: P.157/116/TU/DAMKAR/MPBK/2024 | Q10: 2024
B11: 2 | C11: ADE SUSANTO | G11: PEMADAM 1 | J11: DITJEN BINA ADWIL KEMENDAGRI | M11: P.3/578/TU/SDV/MPBK/2022 | Q11: 2022
B12: 3 | C12: RANU WIBOWO | G12: PEMADAM 1 | J12: DITJEN BINA ADWIL KEMENDAGRI | M12: P.25/240/TU/SDV/MPBK/2022 | Q12: 2022
B13: 4 | C13: IMAM KASTALANI | G13: PEMADAM 1 | J13: DITJEN BINA ADWIL KEMENDAGRI | M13: P.22/238/TU/DAMKAR/MPBK/2024 | Q13: 2024
B14: 5 | C14: AGUS BUDIANTO | G14: PEMADAM 1 | J14: DITJEN BINA ADWIL KEMENDAGRI | M14: P.77/238/TU/DAMKAR/MPBK/2024 | Q14: 2024
B15: 6 | C15: BUDI ADI | G15: PEMADAM 1 | J15: DITJEN BINA ADWIL KEMENDAGRI | M15: P.82/238/TU/DAMKAR/MPBK/2024 | Q15: 2024
B16: 7 | C16: MUHAMMAD NOOR | G16: PEMADAM 1 | J16: DITJEN BINA ADWIL KEMENDAGRI | M16: P.19/141 /TU/DAMKAR/MPBK/2025 | Q16: 2025
B17: 8 | C17: MUHAMMAD FIKRI NISFUADI | G17: PEMADAM 1 | J17: DITJEN BINA ADWIL KEMENDAGRI | M17: P.52/141 /TU/DAMKAR/MPBK/2025 | Q17: 2025
K19: Banjarbaru, Januari 2026
K20: Kepala Satuan Polisi Pamong Praja
K24: DEDY SUTOYO, SSTP, MM.
K25: Pembina Utama Muda
K26: NIP. 19771127 199612 1 001

Sheet SAPRAS
B1: PEMERINTAH KOTA BANJARBARU
B2: SATUAN POLISI PAMONG PRAJA
B3: Alamat : Jl. Pangeran Antasari No. 7 Banjarbaru Kalimantan Selatan
C4: Website : Satpolpp.banjarbarukota.go.id – Email : admin@satpolpp.banjarbarukota.go.id
B6: JENIS SARANA PRASARANA PEMADAMAN, PENYELAMATAN DAN EVAKUASI
B7: UPT PEMADAM KEBAKARAN DAN PENYELAMATAN KOTA BANJARBARU
B9: NO | C9: JENIS SAPRAS | J9: KONDISI | O9: JUMLAH
B10: 1 | C10: Mobil Tangki Hino / Kajama 3500 Liter | J10: Baik | O10: 1 buah
B11: 2 | C11: Mobil Tangki Hino / Kajama 3500 Liter | J11: Baik | O11: 1 buah
B12: 3 | C12: Mobil Tangki Hino / Kajama 4000 Liter | J12: Baik | O12: 1 buah
B13: 4 | C13: Mobil Tangki Hino / Kajama 8000 Liter | J13: Baik | O13: 1 buah
B14: 5 | C14: Mobil Tangki Hino / Kajama 1000 Liter | J14: Baik | O14: 1 buah
B15: 6 | C15: Mobil Rescue Toyota Hilux / Kajama | J15: Baik | O15: 1 buah
B16: 7 | C16: Mobil Tangki Toyota / Gajah / Ton 2 | J16: Tidak Baik | O16: 1 buah
B17: 8 | C17: Mobil Tangki Hino Duetro / Ton 7 | J17: Baik | O17: 1 buah
B18: 9 | C18: Mobil Mesin Pompa Isuzu / 50 / Ton 3 | J18: Baik | O18: 1 buah
B19: 10 | C19: Mobil Mesin Pompa Isuzu / Naruto / Ton 4 | J19: Baik | O19: 1 buah
B20: 11 | C20: Sepeda Motor Honda Vario 160 | J20: Baik | O20: 1 buah
B21: 12 | C21: Tabung Apar | J21: Baik | O21: 7 buah
L24: Banjarbaru, Januari 2026
L25: Kepala Satuan Polisi Pamong Praja
L29: DEDY SUTOYO, SSTP, MM.
L30: Pembina Utama Muda
L31: NIP. 19771127 199612 1 001

Sheet DATA POS 
C2: PEMERINTAH KOTA BANJARBARU
C3: SATUAN POLISI PAMONG PRAJA
C4: Alamat : Jl. Pangeran Antasari No. 7 Banjarbaru Kalimantan Selatan
D5: Website : Satpolpp.banjarbarukota.go.id – Email : admin@satpolpp.banjarbarukota.go.id
B7: POS SEKTOR DAMKAR YANG DILENGKAPI SARANA PRASARANA DAMKAR, PRASARANA PENYELAMATAN DI KECAMATAN
C8: UPT PEMADAM KEBAKARAN DAN PENYELAMATAN KOTA BANJARBARU
B11: NO | C11: KECAMATAN | I11: JUMLAH POS | N11: KETERANGAN
B12: 1 | C12: Banjarbaru Selatan | I12: 1 | N12: Posko UPT Pemadam Kebakaran
M16: Banjarbaru, Januari 2026
M17: Kepala Satuan Polisi Pamong Praja
M21: DEDY SUTOYO, SSTP, MM.
M22: Pembina Utama Muda
M23: NIP. 19771127 199612 1 001

Sheet EVAKUASI
B1: PEMERINTAH KOTA BANJARBARU
B2: SATUAN POLISI PAMONG PRAJA
B3: Alamat : Jl. Pangeran Antasari No. 7 Banjarbaru Kalimantan Selatan
B4: Website : Satpolpp.banjarbarukota.go.id – Email : admin@satpolpp.banjarbarukota.go.id
A6: JENIS LAYANAN PENYELAMATAN DAN EVAKUASI PADA KONDISI MEMBAHAYAKAN MANUSIA
A7: ( OPERASI DARURAT NON KEBAKARAN )
B8: UPT PEMADAM KEBAKARAN DAN PENYELAMATAN KOTA BANJARBARU
B10: DATA TAHUN 2025
A12: NO | B12: HARI/TGL | C12: JAM | G12: INFO VIA | H12: KEGIATAN | I12: Hewan | J12: DLL | K12: KORBAN | M12: JUMLAH | O12: PETUGAS/UNIT OPS | S12: KET
G13: TELP/RADIO | K13: MD (org) | L13: CEDERA | M13: KK | N13: JW
A14: 1 | B14: Rabu, 1 Januari 2025 | C14: 11.39 s/d 12.30 Wita | G14: Kaeni No Telp. 085822521944 | H14: Menindaklanjuti laporan warga perihal meminta bantuan evakuasi anjing yang masuk ke dalam kantor DJKN beralamat Jl. A. Yani Km. 29,5 (Kantor DJKN Kalsel-Teng) Kel. Guntung Manggis Kec. Landasan Ulin. Petugas menuju lokasi pelapor dan anjing dapat di evakuasi oleh pemiliknya. Petugas mengerahkan 1 Unit Ops Damkar Mobil Hilux Kajama Rescue. | I14: 1 | J14: 0 | K14: 0 | L14: 0 | M14: 0 | N14: 0 | O14: 8 orang/1 unit 1. Ranu Wibowo 2. Imam Kastalani 3.M. Fikri Nisfuadi 4. Wahyudi 5. Agus Budianto 6. Ade Susanto 7. Misladin 8. M. Dadang Kurniwan | S14: anjing | T14: 1
A15: 2 | B15: Kamis, 2 Januari 2025 | C15: 20.15 s/d 21.26 Wita | G15: Mara Radliya No telp. 087715559808 | H15: Menindaklanjuti laporan warga perihal meminta bantuan evakuasi sarang lebah yang berada didapur rumah beliau beralamat Jl. Pandok Mangga Komp. Darussalam II No. 2 RT. 19 RW. 08 Kel. Lokatabat Utara Kec. Banjarbaru Utara. Petugas berhasil memusnahkan sarang lebah dengan cara dibakar. Petugas mengerahkan 1 Unit Ops Damkar Mobil Hilux Kajama Rescue. | I15: 1 | J15: 0 | K15: 0 | L15: 0 | M15: 0 | N15: 0 | O15: 6 orang/1 unit 1. Agus Budianto 2. Ade Susanto 3. Misladin 4. M. Yoppie Wirawan 5. Budi Adi 6. Bambang Arry Arsono | S15: lebah | T15: 2
A16: 3 | B16: Jum`at, 3 Januari 2025 | C16: 07.00 s/d 07.50 Wita | G16: Lilik No Telp. 081236301552 | H16: Menindaklanjuti laporan warga perihal meminta bantuan evakuasi anjing yang tercebur kedalam sumur rumah beliau beralamat Jl. Trikora III RT. 42 RW. 08 Kel. Sungai Besar Kec. Banjarbaru Selatan. Petugas menuju lokasi pelapor dan anjing berhasil di evakuasi. Petugas mengerahkan 1 Unit Ops Damkar Mobil Hilux Kajama Rescue. | I16: 1 | J16: 0 | K16: 0 | L16: 0 | M16: 0 | N16: 0 | O16: 6 orang / 1 unit 1. Nur Hidayah, SE 2. Agus Budianto 3. Ade Susanto 4. Misladin 5. M. Yoppie Wirawan 6. M. Dadang Kurniwan | S16: anjing | T16: 3
A17: 4 | B17: Jum`at, 3 Januari 2025 | C17: 16.09 s/d 17.45 Wita | G17: Muhidi Hafi No Telp. 087753517745 | H17: menindaklajuti laporan warga perihal meminta bantuan evakuasi kucing di atas pohon yang menurut pelapor sudah 3 hari tidak bisa turun beralamat Depan Komp. Griya Ulin Permai Jl. Trikora Simpang 4 Berlina Jaya Kel. Landasan Ulin Timur Kec. Landasan Ulin. Kucing berhasil di evakuasi dengan cara disemprot dari bawah. Petugas mengerahkan 1 Unit Ops Damkar Truk Tangki Kajama 4000 Liter. | I17: 1 | J17: 0 | K17: 0 | L17: 0 | M17: 0 | N17: 0 | O17: 8 orang/1 unit 1. Syafrullah, S.Sos, M.Si 2. M. Sairus Sakati 3. Budi Adi 4. Muhammad Noor 5. Bambang Arry Arsono 6. Ranu Wibowo 7. Imam Kastalani 8. M. Fikri Nisfuadi | S17: kucing | T17: 4
A18: 5 | B18: Sabtu, 4 Januari 2025 | C18: 19.03 s/d 19.35 Wita | G18: Waluyo No Telp. 082231978371 | H18: Menindaklanjuti laporan warga perihal meminta bantuan evakuasi ular yang berada di mobil beralamat Jl. A. Yani Km. 36 parkiran wong Solo Simpang 4 Banjarbaru Kel. Komet Kec. Banjarbaru Utara. Petugas menuju lokasi pelapor. Ular berhasil di evakuasi dan dilepasliarkan. Petugas mengerahkan 1 Unit Ops Damkar Mobil Hilux Kajama Rescue. | I18: 1 | J18: 0 | K18: 0 | L18: 0 | M18: 0 | N18: 0 | O18: 8 orang/1 unit 1. Syafrullah, S.sos, M.Si 2. Ranu Wibowo 3. Imam Kastalani 4. M. Fikri Nisfuadi 5. Wahyudi 6. Agus Budianto 7. Misladin 8. M. Yoppie Wirawan | S18: ular | T18: 5
A19: 6 | B19: Minggu, 5 Januari 2025 | C19: 10.15 s/d 11.21 Wita | G19: Nikmah Nufus No Telp. 083876435821 | H19: Menindaklanjuti laporan warga perihal meminta bantuan evakuasi kucing yang berada di dalam sumur rumah beliau beralamat Jl. Kasturi I Blok. A 289 RT. 14 RW. 03 Kel. Sungai Besar Kec. Banjarbaru Selatan. Petugas menuju lokasi pelapor dan kucing berhasil di evakuasi. Petugas mengerahkan 1 Unit Ops Damkar Mobil Hilux Kajama Rescue. | I19: 1 | J19: 0 | K19: 0 | L19: 0 | M19: 0 | N19: 0 | O19: 4 orang/1 unit 1. Agus Budianto 2. Ade Susanto 3. Misladin 4. M. Yoppie Wirawan | S19: kucing | T19: 6
A20: 7 | B20: Senin, 6 Januari 2025 | C20: 05.30 s/d 06.40 Wita | G20: Yuda W No Telp. 085349243372 | H20: Menindaklanjuti laporan warga perihal meminta bantuan evakuasi ular yang berada di dalam rumah beralamat Komp. Dukuh Jaya RT. 10 RW. 07 Kel. Sungai Besar Kec. Banjarbaru Selatan. Petugas langsung menuju lokasi pelapor dan melakukan pencarian. Ular berhasil di evakuasi dan dilepasliarkan. Petugas mengerahkan 1 Unit Ops Damkar Truk Ton III. | I20: 1 | J20: 0 | K20: 0 | L20: 0 | M20: 0 | N20: 0 | O20: 6 orang/1 unit 1. Agus Budianto 2. Ade Susanto 3. Misladin 4. M. Yoppie Wirawan 5. Imam Kastalani 6. M. Dadang Kurniwan | S20: ular | T20: 7
A21: 8 | B21: Senin, 6 Januari 2025 | C21: 11.20 s/d 12.45 Wita | G21: Hery No Telp. 085215519559 | H21: Menindaklanjuti laporan warga perihal meminta bantuan evakuasi tawon yang berada di atas plafon teras rumah beliau beralamat Komp. Citra Bangun PSD Blok D No. 03 RT. 14 RW. 03 Kel. Landasan Ulin Tengah Kec. Liang Anggang. Petugas berhasil memusnahkan tawon dengan cara dibakar. Petugas mengerahkan 1 Unit Ops Damkar Truk Ton VII. | I21: 1 | J21: 0 | K21: 0 | L21: 0 | M21: 0 | N21: 0 | O21: 8 orang/1 unit 1. Syafrullah, S.Sos, M.Si 2. Nur Hidayah, SE 3. M. Sairus Sakati 4. Budi Adi 5. Muhammad Noor 6. Bambang Arry arsono 7. Ranu Wibowo 8. M. Fikri Nisfuadi | S21: tawon | T21: 8
A22: 9 | B22: Selasa, 7 Januari 2025 | C22: 02.17 s/d 02.45 Wita | G22: Nita No Telp. 083141431999 | H22: Minindaklanjuti laporan warga perihal meminta bantuan evakuasi ular di dalam kamar tidur orang tua pelapor beralamat Jl. R.O Ulin RT. 004 RW. 009 No. 09 Kel. Loktabat Selatan Kec. Banjarbaru Selatan. Petugas langsung menuju lokasi pelapor. Ular berhasil di evakuasi dan dilepasliarkan. Petugas mengerahkan 1 Unit Ops Damkar Mobil Hilux Kajama Rescue. | I22: 1 | J22: 0 | K22: 0 | L22: 0 | M22: 0 | N22: 0 | O22: 3 orang/1 unit 1. Budi Adi 2. Muhammad Noor 3. Bambang Arry Arsono | S22: ular | T22: 9
A23: 10 | B23: Selasa, 7 Januari 2025 | C23: 19.45 s/d 20.15 Wita | G23: Septy No Telp. 083186435824 | H23: Menindaklanjuti laporan warga perihal meminta bantuan ular di kamar tidur rumah beliau beralamat Jl. Trikora samping Komp. Pesona Bhayangkara Kel. Guntung Manggis Kec. Landasan Ulin. Petugas langsung menuju lokasi pelapor. Ular berhasil di evakuasi dan dilepasliarkan. Petugas mengerahkan 1 Unit Ops Damkar Mobil Hilux Kajama Rescue. | I23: 1 | J23: 0 | K23: 0 | L23: 0 | M23: 0 | N23: 0 | O23: 8 orang/1 unit 1. Syafrullah, S.Sos, M.Si 2. Nur Hidayah, SE 3. Ranu Wibowo 4. Imam Kastalani 5. M. Fikri Nisfuadi 6. Wahyudi 7. Ade Susanto 8. Misladin | S23: ular | T23: 10
A24: 11 | B24: Rabu, 8 Januari 2025 | C24: 07.52 s/d 08.10 Wita | G24: Halim No Telp. 081645498629 | H24: Menindaklanjuti laporan warga perihal meminta bantuan evakuasi mobil yang terperosok di drainase beralamat Jl. Pandawa Kel. Guntung Paikat Kec. Banjarbaru Selatan. Petugas menuju lokasi pelapor dan mobil berhasil di evakuasi. Petugas emngerahkan 1 Unit Ops Damkar Truk Tangki Kajama 3500 Liter. | I24: 0 | J24: 1 | K24: 0 | L24: 0 | M24: 0 | N24: 0 | O24: 5 orang/1 unit 1. Ranu Wibowo 2. Imam Kastalani 3. M. Fikri Nisfuadi 4. Wahyudi 5. Budi Adi | S24: mobil | T24: 11
A25: 12 | B25: Rabu, 8 Januari 2025 | C25: 12.50 s/d 13.39 Wita | G25: Surya No Telp. 08115046994 | H25: Menindaklanjuti laporan warga perihal meminta bantuan evakuasi ular yang berada dirumah beliau beralamat Komp. Graha Mahkota Damar No. 11 Kel. Syamsudin Noor. Ular berhasil di evakuasi dan dilepasliarkan. Petugas mengerahkan 1 Unit Ops Damkar Mobil Hilux Kajama Rescue. | I25: 1 | J25: 0 | K25: 0 | L25: 0 | M25: 0 | N25: 0 | O25: 8 orang/1 unit 1. Nur Hidayah, SE 2. Agus Budianto 3. Ade Susanto 4. Misladin 5. M. Yoppie Wirawan 6. Muhammad Noor 7. Bambang Arry Arsono 8. M. Dadang Kurniwan | S25: ular | T25: 12
... A555: 542 | B555: Rabu, 31 Desember 2025 | C555: 16.02 s/d 16.35 Wita | G555: M. Baihaqi No Telp. 0895331635307 | H555: Menindaklanjuti laporan warga Umur : 25 Tahun Pekerjaan : Swasta Pendidikan : SMP perihal meminta bantuan evakuasi anak yang yang terkunci dalam WC beralamat Jl. Cempaka Baru Gunung Kupang RT. 40 RW. 10 Kel. Cempaka Kec. Cempaka. Pintu WC berhasil dibuka dan anak berhasil di evakuasi. Petugas mengerahkan 1 Unit Ops Damkar Mobil Hilux Kajama Rescue. | I555: 0 | J555: 1 | K555: 0 | L555: 0 | M555: 0 | N555: 0 | O555: 6 orang/1 unit 1. Syafrullah, S.Sos, M.Si 2. Agus Budianto 3. M. Fikri Nisfuado 4. Cipta Bayu Mukti 5. Heriyanto 6. M. Dadang Kurniwan, S.H. | S555: Orang Terkunci | T555: 38
H559: Banjarbaru, Januari 2026
H560: Kepala Satuan Polisi Pamong Praja
H564: DEDY SUTOYO, SSTP, MM.
H565: Pembina Utama Muda
H566: NIP. 19771127 199612 1 001

Sheet Rekap Evakuasi
A1: REKAP LAPORAN PENYELAMATAN/EVAKUASI TAHUN 2025
A3: NO. | B3: Kegiatan | C3: BULAN | O3: JUMLAH PER KEGIATAN
C4: JANUARI | D4: FEBRUARI | E4: MARET | F4: APRIL | G4: MEI | H4: JUNI | I4: JULI | J4: AGUSTUS | K4: SEPTEMBER | L4: OKTOBER | M4: NOPEMBER | N4: DESEMBER
A5: 1 | B5: Evakuasi Ular | C5: 24 | D5: 25 | E5: 36 | F5: 24 | G5: 25 | H5: 20 | I5: 27 | J5: 23 | K5: 23 | L5: 23 | M5: 28 | N5: 22 | O5: =SUM(C5:N5) -> 300
A6: =A5+1 -> 2 | B6: Evakuasi Kucing | C6: 5 | D6: 1 | E6: 7 | F6: 2 | G6: 5 | H6: 4 | I6: 4 | J6: 2 | K6: 7 | L6: 2 | M6: 5 | N6: 2 | O6: =SUM(C6:N6) -> 46
A7: =A6+1 -> 3 | B7: Evakuasi Anjing | C7: 2 | D7: 1 | E7: 1 | F7: 1 | G7: - | H7: - | I7: - | J7: 2 | K7: - | L7: 1 | M7: 2 | N7: - | O7: =SUM(C7:N7) -> 10
A8: =A7+1 -> 4 | B8: Evakuasi Monyet | C8: 1 | D8: - | E8: - | F8: - | G8: - | H8: 1 | I8: 1 | J8: - | K8: 1 | L8: 3 | M8: 1 | N8: - | O8: =SUM(C8:N8) -> 8
A9: =A8+1 -> 5 | B9: Evakuasi Sarang Tawon | C9: 3 | D9: 1 | E9: - | F9: 1 | G9: 1 | H9: - | I9: 3 | J9: 3 | K9: 1 | L9: 5 | M9: 3 | N9: 2 | O9: =SUM(C9:N9) -> 23
A10: =A9+1 -> 6 | B10: Evakuasi Sarang Lebah | C10: 2 | D10: 1 | E10: 3 | F10: 4 | G10: 3 | H10: 1 | I10: 4 | J10: 1 | K10: 3 | L10: - | M10: - | N10: - | O10: =SUM(C10:N10) -> 22
A11: =A10+1 -> 7 | B11: Evakuasi Biawak | C11: - | D11: 1 | E11: - | F11: - | G11: - | H11: - | I11: 1 | J11: - | K11: - | L11: 1 | M11: - | N11: - | O11: =SUM(C11:N11) -> 3
A12: =A11+1 -> 8 | B12: Evakuasi Musang | C12: 1 | D12: - | E12: - | F12: 2 | G12: 1 | H12: - | I12: 2 | J12: 2 | K12: - | L12: - | M12: 1 | N12: 1 | O12: =SUM(C12:N12) -> 10
A13: =A12+1 -> 9 | B13: Evakuasi Cicak | C13: - | D13: - | E13: - | F13: - | G13: - | H13: - | I13: - | J13: - | K13: - | L13: - | M13: - | N13: - | O13: =SUM(C13:N13) -> 0
A14: =A13+1 -> 10 | B14: Evakuasi Burung | C14: - | D14: - | E14: - | F14: - | G14: - | H14: - | I14: - | J14: 1 | K14: - | L14: - | M14: - | N14: - | O14: =SUM(C14:N14) -> 1
A15: =A14+1 -> 11 | B15: Evakuasi Bekantan | C15: - | D15: - | E15: - | F15: - | G15: - | H15: - | I15: - | J15: - | K15: - | L15: - | M15: - | N15: - | O15: =SUM(C15:N15) -> 0
A16: =A15+1 -> 12 | B16: Evakuasi Tikus | C16: - | D16: - | E16: - | F16: - | G16: - | H16: - | I16: - | J16: 1 | K16: - | L16: - | M16: - | N16: - | O16: =SUM(C16:N16) -> 1
A17: =A16+1 -> 13 | B17: Evakuasi Sigung | C17: - | D17: - | E17: - | F17: - | G17: - | H17: - | I17: - | J17: - | K17: - | L17: 1 | M17: - | N17: - | O17: =SUM(C17:N17) -> 1
A18: =A17+1 -> 14 | B18: Evakuasi Tokek | C18: - | D18: - | E18: - | F18: 1 | G18: - | H18: - | I18: - | J18: - | K18: - | L18: - | M18: - | N18: - | O18: =SUM(C18:N18) -> 1 | S18: =SUM(O5:O18) -> 426
A19: =A18+1 -> 15 | B19: Evakuasi Pohon Tumbang | C19: 2 | D19: 1 | E19: 2 | F19: - | G19: - | H19: - | I19: - | J19: - | K19: 1 | L19: 3 | M19: - | N19: - | O19: =SUM(C19:N19) -> 9
A20: =A19+1 -> 16 | B20: Evakuasi Cincin | C20: - | D20: 2 | E20: 1 | F20: 1 | G20: - | H20: - | I20: - | J20: 2 | K20: - | L20: 1 | M20: 2 | N20: - | O20: =SUM(C20:N20) -> 9
A21: =A20+1 -> 17 | B21: Evakuasi Mobil | C21: 4 | D21: 2 | E21: 1 | F21: - | G21: 2 | H21: 3 | I21: 4 | J21: 7 | K21: 5 | L21: 6 | M21: 3 | N21: 5 | O21: =SUM(C21:N21) -> 42
A22: =A21+1 -> 18 | B22: Evakuasi Handphone | C22: - | D22: - | E22: - | F22: 2 | H22: - | I22: - | J22: 1 | K22: 1 | L22: - | M22: 1 | N22: - | O22: =SUM(C22:N22) -> 5
A23: =A22+1 -> 19 | B23: Evakuasi Kunci Rumah/Kunci Motor/Kunci Mobil/Kunci Ruko | C23: 1 | D23: - | E23: - | F23: 1 | G23: 1 | H23: - | I23: - | J23: - | K23: 1 | L23: - | M23: 2 | N23: 1 | O23: =SUM(C23:N23) -> 7
A24: =A23+1 -> 20 | B24: Evakuasi Pintu | C24: - | D24: - | E24: 2 | F24: 1 | G24: - | H24: 2 | I24: 2 | J24: 1 | K24: 2 | L24: 2 | M24: 3 | N24: 5 | O24: =SUM(C24:N24) -> 20
A25: =A24+1 -> 21 | B25: Evakuasi Ban | C25: - | D25: 1 | E25: - | F25: - | G25: - | H25: - | I25: - | J25: - | K25: - | L25: - | M25: 1 | N25: - | O25: =SUM(C25:N25) -> 2
A26: =A25+1 -> 22 | B26: Evakuasi Tali Tiang Bendera | C26: - | D26: 1 | E26: - | F26: - | G26: - | H26: - | I26: - | J26: - | K26: - | L26: - | M26: - | N26: - | O26: =SUM(C26:N26) -> 1
A27: =A26+1 -> 23 | B27: Evakuasi Orang/Anak Terkunci di Kamar/Kamar Mandi/Dalam Mobil | C27: - | D27: - | E27: 1 | F27: 1 | G27: - | H27: - | I27: - | J27: 1 | K27: 1 | L27: 1 | M27: - | N27: - | O27: =SUM(C27:N27) -> 5
A28: =A27+1 -> 24 | B28: Evakuasi Pagar yang Terkunci | C28: - | D28: - | E28: - | F28: - | G28: - | H28: - | I28: 1 | J28: - | K28: 1 | L28: - | M28: - | N28: - | O28: =SUM(C28:N28) -> 2
A29: =A28+1 -> 25 | B29: Tumpahan Solar | C29: - | D29: - | E29: - | F29: - | G29: 1 | H29: - | I29: - | J29: 1 | K29: - | L29: - | M29: - | N29: - | O29: =SUM(C29:N29) -> 2
A30: =A29+1 -> 26 | B30: Penyemprotan Halaman Kantor | C30: - | D30: - | E30: - | F30: - | G30: - | H30: 1 | I30: - | J30: - | K30: - | L30: - | M30: - | N30: - | O30: =SUM(C30:N30) -> 1
A31: =A30+1 -> 27 | B31: Penyemprotan Drainase | C31: - | D31: - | E31: - | F31: - | G31: - | H31: - | I31: - | J31: - | K31: 1 | L31: - | M31: 2 | N31: - | O31: =SUM(C31:N31) -> 3
A32: =A31+1 -> 28 | B32: Evakuasi Anak/Orang Dewasa Terjepit | C32: - | D32: - | E32: - | F32: - | G32: - | H32: 1 | I32: 1 | J32: - | K32: - | L32: - | M32: - | N32: - | O32: =SUM(C32:N32) -> 2
A33: =A32+1 -> 29 | B33: Bantuan Pengecekan Suara di Plafon | C33: - | D33: - | E33: - | F33: - | G33: - | H33: 1 | I33: - | J33: - | K33: - | L33: - | M33: - | N33: - | O33: =SUM(C33:N33) -> 1
A34: =A33+1 -> 30 | B34: Evakuasi Tabung Gas | C34: - | D34: - | E34: - | F34: - | G34: - | H34: - | I34: - | J34: 1 | K34: - | L34: - | M34: - | N34: - | O34: =SUM(C34:N34) -> 1
A35: =A34+1 -> 31 | B35: Evakuasi Kamera | C35: - | D35: - | E35: - | F35: - | G35: - | H35: - | I35: - | J35: - | K35: - | L35: 1 | M35: - | N35: - | O35: =SUM(C35:N35) -> 1
A36: =A35+1 -> 32 | B36: Evakuasi Mesin air | C36: - | D36: - | E36: - | F36: - | G36: - | H36: - | I36: - | J36: - | K36: - | L36: 1 | M36: - | N36: - | O36: =SUM(C36:N36) -> 1
A37: =A36+1 -> 33 | B37: Evakuasi Orang Pingsan | C37: - | D37: - | E37: - | F37: - | G37: - | H37: 1 | I37: - | J37: - | K37: - | L37: - | M37: - | N37: - | O37: =SUM(C37:N37) -> 1
A38: =A37+1 -> 34 | B38: Evakuasi Orang Tersetrum | C38: - | D38: - | E38: - | F38: - | G38: - | H38: - | I38: - | J38: - | K38: - | L38: 1 | M38: - | N38: - | O38: =SUM(C38:N38) -> 1
B39: JUMLAH | C39: =SUM(C5:C38) -> 45 | D39: =SUM(D5:D38) -> 37 | E39: =SUM(E5:E38) -> 54 | F39: =SUM(F5:F38) -> 41 | G39: =SUM(G5:G38) -> 39 | H39: =SUM(H5:H38) -> 35 | I39: =SUM(I5:I38) -> 50 | J39: =SUM(J5:J38) -> 49 | ... N39: =SUM(N5:N38) -> 38 | O39: =SUM(C39:N39) -> 542
C41: =C39+D39+E39 -> 136 | F41: =F39+G39+H39 -> 115 | I41: =I39+J39+K39 -> 147 | L41: =L39+M39+N39 -> 144
B44: Animal Rescue | C44: =SUM(C5:C18) -> 38 | D44: =SUM(D5:D18) -> 30 | E44: =SUM(E5:E18) -> 47 | F44: =SUM(F5:F18) -> 35 | G44: =SUM(G5:G18) -> 35 | H44: =SUM(H5:H18) -> 26 | I44: =SUM(I5:I18) -> 42 | J44: =SUM(J5:J18) -> 35 | ... N44: =SUM(N5:N18) -> 27 | O44: =SUM(C44:N44) -> 426
...

Sheet RESPONSE TIME
B2: PEMERINTAH KOTA BANJARBARU
B3: SATUAN POLISI PAMONG PRAJA
B4: Alamat : Jl. Pangeran Antasari No. 7 Banjarbaru Kalimantan Selatan
B5: Website : Satpolpp.banjarbarukota.go.id – Email : admin@satpolpp.banjarbarukota.go.id
A7: RATA-RATA WAKTU TANGGAP (RESPONSE TIME) PENANGANAN KEBAKARAN
A8: UPT PEMADAM KEBAKARAN DAN PENYELAMATAN KOTA BANJARBARU
A9: TAHUN 2025
A12: NO | B12: HARI/TGL | C12: JAM | D12: JAM | H12: INFO VIA | I12: KEGIATAN | J12: YG TERBAKAR | L12: Hewan | M12: DLL | N12: KORBAN | P12: JUMLAH | R12: PENYEBABNYA | S12: PETUGAS/UNIT OPS | W12: RESPONSE TIME | X12: SATUAN | Y12: KET
C13: LAPORAN DITERIMA | H13: TELP/RADIO | J13: LAHAN | K13: BANGUNAN | N13: MD (org) | O13: CEDERA | P13: KK | Q13: JW | X13: JAM
A14: 1 | B14: Selasa, 14 Januari 2025 | C14: 07.46 Wita | D14: 08.04 s/d 09.09 Wita | H14: Satria No Telp. 085654789903 | I14: Menindaklanjuti laporan warga perihal telah terjadi kebakaran bangunan beralamat Jl. A. Yani Km, 22 Gang Antara RT. 04 RW. 02 Depot Rezky Rasa Mie Ayam Kel. Landasan Ulin Tengah Kec. Liang Anggang. Petugas langsung menuju lokasi kejadian. Pemilik an. Bapak Dwi Hartanto kerugian diperirakan kurang lebih 8 Juta Rupiah. Asal api kebocoran selang regulator. Petugas mengerahkan 2 Unit Ops Damkar Truk Tangki Kajama 3500 Liter dan Truk Tangki Kajama 4000 Liter | J14: 0 | K14: 1 | L14: 0 | M14: 0 | N14: 0 | O14: 0 | P14: 1 | Q14: 1 | R14: kebocoran selang regulator | S14: 11 orang/2 unit 1. Syafrullah, S.Sos, M.Si 2. Nur Hidayah, SE 3. Agus Budianto 4. Ade Susanto 5. Misladin 6. M. Yoppie Wirawan 7. Ranu Wibowo 8. M. Fikri Nisfuadi 9. Budi Adi 10. Muhammad Noor 11. M. Dadang Kurniwan | W14: 18 | X14: Menit | Y14: Warung Makan
A15: 2 | B15: Jum`at, 24 Januari 2025 | C15: 14.46 Wita | D15: 15.04 s/d 16.30 Wita | H15: Ibu Ida No Hp. 083836466700 | I15: Menindaklanjuti laporan warga an. Dayah No Telp. 085246151554 perihal telah terjadi kebakaran bangunan beralamat Jl. Kasturi 2 Komp. Sumber Cahaya Indah RT. 38 RW. 06 Kel. Syamsudin Noor Kec. Landasan Ulin. Kerugian yang ditimbulkan menghanguskan peralatan dapur dan 50% bangunan terbakar. Pemilik atas nama Bapak Gery Suharto 1 KK 1 Jiwa. Asal api arus pendek listrik. Petugas mengerahkan 1 Unit Ops Damkar Truk Tangki Kajama 3500 Liter. | J15: 0 | K15: 1 | L15: 0 | M15: 0 | N15: 0 | O15: 0 | P15: 1 | Q15: 1 | R15: belum diketahui | S15: 9 orang/1 unit 1. Syafrullah, S.Sos, M.Si 2. Nur Hidayah, SE 3. M. Sairus Sakati 4. Budi Adi 5. Muhammad Noor 6. Bambang Arry Arsono 7. Imam Kastalani 8. M. Fikri Nisfuadi 9. M. Dadang Kurniwan | W15: 18 | X15: Menit | Y15: Rumah
A16: 3 | B16: Rabu, 12 Februari 2025 | C16: 21.44 Wita | D16: 22.01 s/d 23.50 Wita | H16: an. Satria No Telp. 085654789903 | I16: Menindaklanjuti laporan warga perihal telah terjadi kebakaran bangunan Toko sekaligus tempat tinggal beralamat Jl. A. Yani Km. 24 RW. 08 RW. 03 Kel. Landasan Ulin Tengah Kec. Liang Anggang. Pemilik an. Astinah yang disewakan dan ditempati oleh Mama Riza 1 KK 5 Jiwa. Asal api masih dalam tahap penyelidikan Kepolisian. Kerugian diperkirakan 100 Juta Rupiah. Petugas menegerahkan 2 Unit Ops Damkar Truk Tangki Kajama 3500 liter dan 4000 liter. | J16: 0 | K16: 1 | L16: 0 | M16: 0 | N16: 0 | O16: 0 | P16: 1 | Q16: 5 | R16: belum diketahui | S16: 5 orang/1 unit 1. Ranu Wibowo 2. Imam Kastalani 3. M. Fikri Nisfuadi 4. Muhammad Noor 5. Bambang Arry Arsono | W16: 17 | X16: Menit | Y16: Toko
A17: 4 | B17: Kamis, 27 Februari 2025 | C17: 14.5 Wita | D17: 15.10 s/d 16.20 Wita | H17: Grup WA Emergency Banjarbaru | I17: Menindaklanjuti laporan warga bahwa telah terjadi kebakaran bangunan rumah warga yang beralamat Jl. Ara Budi RT. 12 RW. 03 Kel. Landasan Ulin Tengah Kec. Liang Anggang. Pemilik an. Isran 1 KK 4 Jiwa asal api dalam tahap penyelidian kepolisian. Bangunan habis terbakar dan Kerugian diperkirakan 300 Juta Rupiah. Petugas mengerahkan 2 Unit Ops Damkar Truk Tangki Kajama 3500 Liter. | J17: 0 | K17: 1 | L17: 0 | M17: 0 | N17: 0 | O17: 0 | P17: 1 | Q17: 4 | R17: belum diketahui | S17: 12 orang/2 unit 1. Syafrullah, S.Sos, M.Si 2. Ranu Wibowo 3. Imam Kastalani 4. M. Fikri Nisfuadi 5. Agus Budianto 6. Ade Susanto 7. Misladin 8. M. Yoppie Wirawan 9.. Budi Adi 10. Muhammad Noor 11. Bambang Arry Arsono 12. M. Dadang Kurniwan | W17: 15 | X17: Menit | Y17: kandang ayam
A18: 5 | B18: Jum`at, 28 Maret 2025 | C18: 11.15 Wita | D18: 11.30 s/d 12.45 Wita | H18: Didi (Lurah Bangkal) No Hp. 081348419333 | I18: Menindaklanjuti laporan warga perihal telah terjadi kebakaran bangunan di Sekolah Dasar Negeri 1 Bangkal beralamat Jl. Mistarcokrokusumo RT. 03 RW. 01 Kel. Bangkal Kec. Cempaka. Petugas menuju lokasi kejadian dan melakukan pembongkaran atap dikarenakan titik api di bagian atas atap plafon ruang Tata Usaha yang mengeluarkan asap. Penyebab kebakaran arus pendek listrik. Petugas mengerahkan 1 Unit Ops Damkar Truk Tangki Kajama 3500 Liter. | J18: 0 | K18: 1 | L18: 0 | M18: 0 | N18: 0 | O18: 0 | P18: 0 | Q18: 0 | R18: belum diketahui | S18: 6 orang/1 unit 1. Budi Adi 2. Muhammad Noor 3. Bambang Arry Arsono 4. Ranu Wibowo 5. Imam Kastalani 6. M. Fikri Nisfuadi | W18: 15 | X18: Menit | Y18: SD Bangkal 1
A19: 6 | B19: Minggu, 30 Maret 2025 | C19: 18.42 Wita | D19: 18.57 s/d 19.54 Wita | H19: Muhammad Syarkawi No Telp. 081649770559 | I19: Menindaklanjuti laporan warga perihal telah terjadi kebakaran bangunan beralamat Jl. H. Mistarcokrokusumo RT. 11 RW. 04 Kel. Cempaka Kec. Cempaka. Pemilik Rumah An. Muhammad Kausar 50 Tahun asal api dari kompor yang ditinggalkan pemiliknya. Jumlah kerugian kurang lebih 20 Juta Rupiah. Petugas mengerahkan 2 Unit Ops Damkar Truk Tangki Kajama 3500 Liter dan 4000 Liter. | J19: 0 | K19: 1 | L19: 0 | M19: 0 | N19: 0 | O19: 0 | P19: 1 | Q19: 2 | R19: Kompor | S19: 11 orang/ 2 unit 1. Syafrullah, S.Sos, M.Si 2. Agus Budianto 3. Ade Susanto 4. Misladin 5. M. Yoppie Wirawan 6. Ranu Wibowo 7. Imam Kastalani 8. M. Fikri Nisfuadi 9. Budi Adi 10. Muhammad Noor 11. Bambang Arry Arsono | W19: 15 | X19: Menit | Y19: Rumah
A20: 7 | B20: Sabtu, 5 April 2025 | C20: 19.25 Wita | D20: 19.35 s/d 20.19 Wita | H20: via grup emergency | I20: Menindaklanjuti laporan Via Grup Wa Relawan Damkar Banjarbaru telah terjadi kebakaran bangunan di Rumah Makan Mie Goyang beralamat Jl. Pinus 2 RT. 02 RW. 02 Kel. Mentaos Kec. Banjarbaru Utara. Asal api dari Tabung Gas yang bocor. Kerugian kurang lebih 9 Juta Rupiah. Korban Luka Bakar an. Yasin, Abdullah dan Ridani Pegawai Rumah Makan Mie Goyang. Petugas mengerahkan 1 Unit Ops Damkar Truk Tangki Kajama 4000 Liter. | J20: 0 | K20: 1 | L20: 0 | M20: 0 | N20: 0 | O20: 0 | P20: 0 | Q20: 0 | R20: Tabung Gas Bocor | S20: 7 orang/1 unit 1. Agus Budianto 2. Ade Susanto 3. Misladin 4. M. Yoppie Wirawan 5. Budi Adi 6. Muhammad Noor 7. Bambang Arry Arsono | W20: 10 | X20: Menit | Y20: Rumah Makan | Z20: 1
A21: 8 | B21: Senin, 7 April 2025 | C21: 01.16 | D21: 01.31 s/d 03.15 Wita | H21: via grup emergency an. Rokhlis Alwi No Telp. 085387589102 | I21: Menindaklanjuti laporan dari Grup Wa Emergency Banjarbaru an. Rokhlis Alwi No Telp. 085387589102 telah terjasi kebakaran bangunan Ruko 2 Lantai tempat usaha Loundry beralamat Jl. Karang So RT. 20 RW. 11 No. 04 Kel. Loktabat Utara Kec. Banjarbaru Utara. Asal api masih dalam tahap penyelidikan kepolisian. Terdampak Ruko 2 lantai habis terbakar. Korban mengalami syok karyawati an. Musda 19 Tahun dan Maria 20 Tahun. Pemilik Usaha an. Ibu Alfisyah 55 Tahun. Petugas mengerahkan 1 Unit Ops Damkar Truk tangki Kajama 3500 Liter. | J21: 0 | K21: 1 | L21: 0 | M21: 0 | N21: 0 | O21: 0 | P21: 0 | Q21: 0 | R21: belum diketahui | S21: 4 orang/1 unit 1. Budi Adi 2. Muhammad Noor 3. Bambang Arry Arsono 4. M. Yoppie Wirawan | W21: 15 | X21: Menit | Y21: Ruko Usaha Loundry | Z21: 2
A22: 9 | B22: Selasa, 8 April 2025 | C22: 20.20 Wita | D22: 20.38 s/d 22.00 Wita | H22: Via Grup WA Relawan Damkar | I22: Menindaklanjuti laporan Via Grup WA Relawan Damkar bahwa terjadi kebakaran bangunan beralamat Jl. Jurusan Pleihari/ pembataan No. 76 RT. 06 RW. 02 Kel. Landasan Ulin Selatan Kec. Liang Anggang. Pemilik rumah an. Abdul Rahman (Ubay) 2 KK 6 Jiwa an. Abdul Rahman 73 Tahun, Atikah 41 Tahun. Asal api masih dalam penyelidikan kepolisian.Kerugian diperkirakan 90 juta Rupiah. Petugas mengerahkan 2 Unit Ops Damkar Truk Tangki Kajama 4000 Liter dan Mobil Hilux Kajama Rescue. | J22: 0 | K22: 1 | L22: 0 | M22: 0 | N22: 0 | O22: 0 | P22: 2 | Q22: 6 | R22: belum diketahui | S22: 6 orang/ 2 unit 1. Agus Budianto 2. Ade Susanto 3. Misladin 4. M. Yoppie Wirawan 5. Budi Adi 6. Muhammad Noor | W22: 18 | X22: Menit | Y22: Rumah | Z22: 3
A23: 10 | B23: Kamis, 10 April 2025 | C23: 00.51 Wita | D23: 01.06 s/d 02.45 Wita | H23: Amau No Telp. 083141012072 | I23: Menindaklanjuti lapiran warga an. Amau No Telp. 083141012072 perihal telah terjadi kebakaran bangunan beralamat Jl. Laros RT. 04 RW. 02 Kec. Landasan Ulin Tengah Kec. Liang Anggang. Pemilik an. Ibu Yusnani 50 tahun. Asal api masih dalam tahap penyelidikan kepolisian. Terdampak Rumah tebakar 70% berserta isi nya. Petugas mengerahkan 1 Unit Ops Damkar Truk Tangki Kajama 3500 Liter. | J23: 0 | K23: 1 | L23: 0 | M23: 0 | N23: 0 | O23: 0 | P23: 0 | Q23: 0 | R23: belum diketahui | S23: 3 orang/1 unit 1. Budi Adi 2. Muhammad Noor 3. Bambang Arry Arsono | W23: 15 | X23: Menit | Y23: Rumah | Z23: 4
A24: 11 | B24: Senin, 14 April 2025 | C24: 10.40 Wita | D24: 10.54 s/d 12.10 Wita | H24: Rizal No Telp. 083179456344 | I24: Menindaklanjuti laporan warga an. Rizal No Telp. 083179456344 perihal telah terjadi kebakaran bangunan beralamat Komp. Angkasa Golf Indah Blok B1 RT. 28 RW. 06 Kel. Syamsudin Noor Kec. Landasan Ulin. Laporan awal diterima pada pukul 10.44 Wita. Pemilik an. Imam 1 KK 5 Jiwa an. Eva Darma Yanti. Perkiraan kerugian 90 Juta Rupiah. Asal api masih dalam penyelidikan Kepolisian. Petugas mengerahkan 2 Unit Ops Damkar Truk Tangki Kajama 3500 Liter dan 4000 Liter. | J24: 0 | K24: 1 | L24: 0 | M24: 0 | N24: 0 | O24: 0 | P24: 1 | Q24: 5 | R24: belum diketahui | S24: 8 orang/2 unit 1. Nur Hidayah, SE 2. Agus Budianto 3. Ade Susanto 4. Misladin 5. M. Yoppie Wirawan 6. Budi Adi 7. Muhammad Noor 8. M. Dadang Kurniwan, S.H. | W24: 14 | X24: Menit | Y24: Rumah | Z24: 5
A25: 12 | B25: Selasa, 15 April 2025 | C25: 22.42 Wita | D25: 22.40 s/d 00.30 Wita | H25: Satria N No Telp. 085654783903 | I25: Menindaklanjuti laporan warga an. Satria N No Telp. 085654783903 perihal telah terjadi kebakaran bangunan beralamat Jl. Sidomulyo Raya RT. 02 Rw. 09 Gg. Kamila Kel. Landasan Ulin Timur Kec. Landasan Ulin. Pemilik an. Bapak Dian Aji Mulya dan Istri Raida 1 KK 4 Jiwa. Rumah berukuran 3X11 Meter terbakar sekitar 70% bangunan beserta isi 5 Buah Sepeda Motor 3 Mobil terbakar ringan. Kerugian diperkirakan 450 Juta Rupiah. Asal api masih dalam tahap penyelidikan kepolisian. Petugas mengerahakn 2 Unit Ops Damkar Truk Tangki Kajama 3500 Liter dan 4000 Liter. | J25: 0 | K25: 1 | L25: 0 | M25: 0 | N25: 0 | O25: 0 | P25: 1 | Q25: 4 | R25: belum diketahui | S25: 10 orang/2 unit 1. Syafrullah, S.Sos, M.Si 2. Budi Adi 3. Muhammad Noor 4. Bambang Arry Arsono 5. Agus Budianto 6. Ade Susanto 7. Misladin 8. M. Yoppie Wirawan 9. Ranu Wibowo 10. M. Fikri Nisfuadi | W25: 16 | X25: Menit | Y25: Rumah | Z25: 6
A26: 13 | B26: Minggu, 20 April 2025 | C26: 06.20 Wita | D26: 06.30 s/d 08.20 Wita | H26: Ulil No Telp. 087735583638 | I26: Menindaklanjuti laporan warga an. Ulil No Telp. 087735583638 perihal telah terjadi kebakaran bangunan Jl. Nusantara Komp. Berlina Jaya No. 44 RT. 03 RW. 05 Kel. Loktabat Selatan Kec. Banjarbaru Selatan. Pemilik an. Sadriansyah 1 KK 2 Jiwa. Asal api masih dalam tahap penyelidikan kepolisian. Korban an. Sadriansyah luka bakar bakar ringan. an. tukang tabung oksigen luka bakar berat tangan kiri di bawa kerumah sakit. Kerugian 100 Juta Rupiah. Petugas melakukan pemadaman, pendinginan dan pengecekan ulang bahwa api dinyatakan padam. Petugas mengerahkan 1 Unit Ops Damkar Truk Tangki Kajama 3500 Liter. | J26: 0 | K26: 1 | L26: 0 | M26: 0 | N26: 0 | O26: 0 | P26: 1 | Q26: 2 | R26: belum diketahui | S26: 4 orang/1 unit 1. Ranu Wibowo 2. Imam Kastalani 3. M Firi Nisfuadi 4. Budi Adi | W26: 10 | X26: menit | Y26: Rumah | Z26: 7
A27: 14 | B27: Minggu, 20 April 2025 | C27: 20.47 Wita | D27: 21.00 s/d 22.05 Wita | H27: Via Grup WA Emergency Banjarbaru | I27: Menindaklanjuti laporan Via Wa Emergency Banjarbaru telah terjadi kebakaran bangunan an. Bapak Gonarsih Jl. Bhayangkara Gg. Perintis RT. 35 RW. 07 Kel. Sungai Ulin Kec. Banjarbaru Utara. 1 KK 2 Jiwa. Kerugian kurang lebih 10 Juta Rupiah. Petugas mengerahkan 2 Unit Ops Damkar Truk Tangki Kajama 3500 liter dan 4000 liter. | J27: 0 | K27: 1 | L27: 0 | M27: 0 | N27: 0 | O27: 0 | P27: 1 | Q27: 2 | R27: belum diketahui | S27: 7 orang/2 unit 1.. Syafrullah, S.Sos, M.Si 2. Agus Budianto 3. Ade Susanto 4. Misladin 5. M. Yoppie Wirawan 6. Bambang Arry Arsono 7. M. Dadang Kurniwan, S.H | W27: 13 | X27: Menit | Y27: Rumah | Z27: 8
A28: 15 | B28: Jum`at, 2 Mei 2025 | C28: 20.12 Wita | D28: 20.25 s/d 21.26 Wita | H28: Grup WA emergency Kota Banjarbaru | I28: Menindaklanjuti laporan Gup WA Emergency Banjarbaru tentang adanya kebakaran bangunan beralamat Jl. PM. Noor Komp. Kondang Buana Asri RT. 29 RW. 07 Kel. Sungai Ulin Kec. Bajarbaru Utara. 1 Buah Rumah terbakar pemilik an. Ice Trinawatih umur 42 Tahun, kerugian diperkirakan 70 Juta Rupiah. Asal api masih dalam tahap penyelidikan kepolisian. Petugas mengerahkan 1 Unit Ops Damkar Truk Tangki 3500 Liter. | J28: 0 | K28: 1 | L28: 0 | M28: 0 | N28: 0 | O28: 0 | P28: 0 | Q28: 0 | R28: belum diketahui | S28: 8 orang/1 unit 1, Syafrullah, S.Sos, M.Si 2. Agus Budianto 3. Ade Susanto 4. Misladin 5. M Yoppie Wirawan 6. Budi Adi 7. Muhammad Noor 8. Bambang Arry Arsono | W28: 13 | X28: Menit | Y28: Rumah | Z28: 1
A29: 16 | B29: Sabtu, 3 Mei 2025 | C29: 08.44 Wita | D29: 09.01 s/d 10.30 Wita | H29: Agus No Telp. 081220867198 | I29: Menindaklanjuti laporan warga an. Agus No Telp. 081220867198 perihal telah terjadi kebakaran bangunan berlamat Jl. Kong EX RT. 14 RW. 04 Kel. Landasan Ulin Barat Kec. Liang Anggang. Bangunan terbuat dari kayu habis terbakar yang di pakai tempat usaha Laundry, Pemilik an. Natuliana usia 54 Tahun di huni 1 KK 2 Jiwa. Kerugian di perikrakan 45 Juta Rupiah. Asal api masih dalam tahap penyelidikan kepolisian. Petugas mengerahkan 1 Unit Ops Damkar Truk Tangki Kajama 3500 Liter. | J29: 0 | K29: 1 | L29: 0 | M29: 0 | N29: 0 | O29: 0 | P29: 1 | Q29: 2 | R29: belum diketahui | S29: 8 orang/ 1 unit 1. Nur Hidayah, SE 2. Budi Adi 3. Muhammad Noor 4. Bambang Arry Arsono 5. Ranu Wibowo 6. Imam Kastalani 7. M. Fikri Nisfuadi 8. M. Dadang Kurniwan, S.H. | W29: 17 | X29: Menit | Y29: Toko Kayu Laoundry | Z29: 2
A30: 17 | B30: Senin, 5 Mei 2025 | C30: 22.58 Wita | D30: 23.15 s/d 00.10 Wita | H30: Via WA Grup Emergency | I30: Menindaklanjuti laporan Via WA Grup Emergency telah terjadi kebakaran bangunan beralamat Jl. Lingkar Utara RT. 38 RW. 06 Kel. Syamsudin Noor Kec. Landasan Ulin. Pemilik an. Rahman 1 KK 2 Jiwa, 1 KK 1 Jiwa. 1 orang mengalami luka bakar tangan kiri kaki kiri istri Rahman. Asal api masih dalam penyelidikan kepolisian. Kerugian diperkirakan 200 Juta Rupiah. Petugas mengerahkan 1 Unit Ops Damkar Truk Tangki Kajama 3500 Liter. | J30: 0 | K30: 1 | L30: 0 | M30: 0 | N30: 0 | O30: 0 | P30: 2 | Q30: 3 | R30: belum diketahui | S30: 13 orang/1 unit 1. Syafrullah, S.Sos, M.Si 2. Nur Hidayah, SE 3. Agus Budianto 4. Ade Susanto 5. Misladin 6. M. Yoppie Wirawan 7. Budi Adi 8. Muhammad Noor 9. Bambang Arry Arsono 10. Ranu Wibowo 11. Imam Kastalani 12. M. Fikri Nisfuadi 13. M. Dadang Kurniwan, S.H. | W30: 17 | X30: Menit | Y30: Rumah | Z30: 3
A31: 18 | B31: Selasa, 6 Mei 2025 | C31: 02.15 Wita | D31: 02.30 s/d 03.27 Wita | H31: Grup WA Emergency | I31: Menindaklanjuti laporan Grup WA Emergency Bares telah terjadi kebakaran bangunan rumah beralamat Jl. Mistarcokrokusumo RT. 03 RW. 01 Kel. Bangkal Kec. Cempaka. Pemilik an. Turiah 1 KK 1 Jiwa. Kerugian diperkirakan 250 Juta Rupiah. Asal api masih dalam penyelidikan kepolisian. Petugas mengerahkan 2 Unit Ops Damkar 2 Truk Tangki Kajama 3500 Liter. | J31: 0 | K31: 1 | L31: 0 | M31: 0 | N31: 0 | O31: 0 | P31: 1 | Q31: 1 | R31: belum diketahui | S31: 4 orang/2 unit 1. Agus Budianto 2. Ade Susanto 3. Misladin 4. M Yoppie Wirawan | W31: 15 | X31: Menit | Y31: Rumah | Z31: 4
... A59: 46 | B59: Minggu, 28 Desember 2025 | C59: 21.19 Wita | D59: 21.31 s/d 22.55 Wita | H59: Via Grup Emergency Banjarbaru | I59: Menindaklanjutin laporan warga melalui Grup WA Emergency Banjarbaru perihal telah terjadi kebakaran bangunan beralamat Jl. Mistarcokrokusumo RT. 05 RW. 02 Kel. Bangkal Kec. Cempaka 1 Buah bangunan kandang ayam dalam keadaan kosong telah terbakar habis. Pemilik an. H. Jani Umur : 57 Tahun. Petugas mengerahkan 2 Unit Ops Damkar Truk Tangki Kajama 3500 dan 4000 Liter. | J59: 0 | K59: 1 | L59: 0 | M59: 0 | N59: 0 | O59: 0 | P59: 0 | Q59: 0 | R59: belum diketahui | S59: 14 orang/2 unit 1. Syafrullah, S.Sos, M.Si 2. Agus Budianto 3. M. Fikri Nisfuadi 4. Cipta Bayu Mukti 5. Heriyanto 6. Budi Adi 7. Ade Susanto 8. Muhammad Noor 9. Bambang Arry Arsono 10. M. Yoppie Wirawan 11. Ranu Wibowo 12. Imam Kastalani 13. Ahmad Riduan 14. Muhammad Noor, SE | W59: 12 | X59: Menit | Y59: kandang ayam | Z59: 3
B60: JUMLAH | J60: =SUM(J14:J59) -> 0 | K60: =SUM(K14:K59) -> 49 | L60: =SUM(L14:L59) -> 0 | M60: =SUM(M14:M59) -> 0 | N60: =SUM(N14:N59) -> 0 | O60: =SUM(O14:O59) -> 0 | P60: =SUM(P14:P59) -> 37 | Q60: =SUM(Q14:Q59) -> 86 | W60: =SUM(W14:W59) -> 654 | X60: MENIT
U61: Respon Time | W61: =W60/A59 -> 14.217391
J66: Banjarbaru, Januari 2026
J67: Kepala Satuan Polisi Pamong Praja
J71: DEDY SUTOYO, SSTP, MM.
J72: Pembina Utama Muda
J73: NIP. 19771127 199612 1 001

Sheet Sheet2
A1: Jumlah Response Time Penanganan Kebakaran
A3: YG TERBAKAR | C3: Hewan | D3: DLL | E3: KORBAN | G3: JUMLAH | I3: RESPONSE TIME | J3: SATUAN | L3: JUMLAH WAKTU | M3: JUMLAH KEGIATAN | N3: RATA-RATA
A4: LAHAN | B4: BANGUNAN | E4: MD (org) | F4: CEDERA | G4: KK | H4: JW | J4: JAM | N4: RESPONSE TIME
A5: ='RESPONSE TIME'!J60 -> 0 | B5: ='RESPONSE TIME'!K60 -> 49 | C5: ='RESPONSE TIME'!L60 -> 0 | D5: ='RESPONSE TIME'!M60 -> 0 | E5: ='RESPONSE TIME'!N60 -> 0 | F5: ='RESPONSE TIME'!O60 -> 0 | G5: ='RESPONSE TIME'!P60 -> 37 | H5: ='RESPONSE TIME'!Q60 -> 86 | I5: ='RESPONSE TIME'!W60 -> 654 | J5: ='RESPONSE TIME'!X60 -> MENIT | L5: =I5 -> 654 | M5: 46 | N5: =L5/M5 -> 14.217391 | O5: MENIT

Sheet Rekap Kebakaran 2025
A1: NO. | B1: KECAMATAN / KELURAHAN | C1: REKAP KEBAKARAN UPT PEMADAM KEBAKARAN KOTA BANJARBARU | O1: JUMLAH PER KEC. / KEL.
C2: TAHUN 2025
C3: JANUARI | D3: FEBRUARI | E3: MARET | F3: APRIL | G3: MEI | H3: JUNI | I3: JULI | J3: AGUSTUS | K3: SEPTEMBER | L3: OKTOBER | M3: NOPEMBER | N3: DESEMBER
B4: Kecamatan Banjarbaru Utara | O4: =SUM(O5:O8) -> 10
A5: 1 | B5: Kelurahan Komet | G5: 1 | L5: 1 | O5: =SUM(C5:N5) -> 2
A6: 2 | B6: Kelurahan Mentaos | F6: 1 | G6: 1 | O6: =SUM(C6:N6) -> 2
A7: 3 | B7: Kelurahan Loktabat Utara | F7: 1 | L7: 1 | O7: =SUM(C7:N7) -> 2
A8: 4 | B8: Kelurahan Sungai Ulin | F8: 1 | G8: 1 | I8: 1 | N8: 1 | O8: =SUM(C8:N8) -> 4
B10: Kecamatan Banjarbaru Selatan | O10: =SUM(O11:O14) -> 8
A11: 1 | B11: Kelurahan Guntung Paikat | J11: 1 | O11: =SUM(C11:N11) -> 1
A12: 2 | B12: Kelurahan Kemuning | I12: 1 | L12: 1 | O12: =SUM(C12:N12) -> 2
A13: 3 | B13: Kelurahan Loktabat Selatan | F13: 1 | G13: 1 | H13: 1 | K13: 1 | O13: =SUM(C13:N13) -> 4
A14: 4 | B14: Kelurahan Sungai Besar | K14: 1 | O14: =SUM(C14:N14) -> 1
B16: Kecamatan Cempaka | O16: =SUM(O17:O20) -> 5
A17: 1 | B17: Kelurahan Cempaka | E17: 1 | O17: =SUM(C17:N17) -> 1
A18: 2 | B18: Kelurahan Sungai Tiung | O18: =SUM(C18:N18) -> 0
A19: 3 | B19: Kelurahan Bangkal | E19: 1 | G19: 1 | M19: 1 | N19: 1 | O19: =SUM(C19:N19) -> 4
A20: 4 | B20: Kelurahan Palam | O20: =SUM(C20:N20) -> 0
B22: Kecamatan Landasan Ulin | O22: =SUM(O23:O26) -> 11
A23: 1 | B23: Kelurahan Guntung Manggis | G23: 2 | I23: 1 | J23: 1 | K23: 2 | O23: =SUM(C23:N23) -> 6
A24: 2 | B24: Kelurahan Guntung Payung | O24: =SUM(C24:N24) -> 0
A25: 3 | B25: Kelurahan Landasan Ulin Timur | F25: 1 | N25: 1 | O25: =SUM(C25:N25) -> 2
A26: 4 | B26: Kelurahan Syamsudin Noor | C26: 1 | F26: 1 | G26: 1 | O26: =SUM(C26:N26) -> 3
B28: Kecamatan Liang Anggang | O28: =SUM(O29:O32) -> 12
A29: 1 | B29: Kelurahan Landasan Ulin Barat | G29: 1 | K29: 1 | O29: =SUM(C29:N29) -> 2
A30: 2 | B30: Kelurahan Landasan Ulin Selatan | F30: 1 | J30: 1 | O30: =SUM(C30:N30) -> 2
A31: 3 | B31: Kelurahan Landasan Ulin Tengah | C31: 1 | D31: 2 | F31: 1 | H31: 1 | K31: 1 | M31: 1 | O31: =SUM(C31:N31) -> 7
A32: 4 | B32: Kelurahan Landasan Ulin Utara | L32: 1 | O32: =SUM(C32:N32) -> 1
B33: JUMLAH | C33: =SUM(C4:C32) -> 2 | D33: =SUM(D4:D32) -> 2 | E33: =SUM(E4:E32) -> 2 | F33: =SUM(F4:F32) -> 8 | G33: =SUM(G4:G32) -> 9 | H33: =SUM(H4:H32) -> 2 | I33: =SUM(I4:I32) -> 3 | J33: =SUM(J4:J32) -> 3 | ... N33: =SUM(N4:N32) -> 3 | O33: =SUM(C33:N33) -> 46
