Workbook

Sheet RELAWAN
C2: PEMERINTAH KOTA BANJARBARU
C3: SATUAN POLISI PAMONG PRAJA
C4: Alamat : Jl. Pangeran Antasari No. 7 Banjarbaru Kalimantan Selatan
C5: Website : Satpolpp.banjarbarukota.go.id – Email : admin@satpolpp.banjarbarukota.go.id
C7: RELAWAN KEBAKARAN
C8: BINAAN UPT PEMADAM KEBAKARAN DAN PENYELAMATAN
C9: KOTA BANJARBARU
C11: NO | D11: NIK | E11: NAMA
C12: 1 | D12: 1207281310850003 | E12: SURYA DARMA
C13: 2 | D13: 6203052802820002 | E13: ABASUDIN
C14: 3 | D14: 6203174508970002 | E14: SITI HAJAR
C15: 4 | D15: 6206020109960001 | E15: MUHAMMAD NORTAJLI
C16: 5 | D16: 6301042409900001 | E16: BADRIANOR
C17: 6 | D17: 6301050206040001 | E17: HAFIF ANSARI
C18: 7 | D18: 6301050506850005 | E18: NUR IFANSYAH
C19: 8 | D19: 6301052601030008 | E19: MUHAMMAD SOLEHIN
C20: 9 | D20: 6301052806050001 | E20: M.SURYA
C21: 10 | D21: 6301094403000004 | E21: ANNISA FITRIANY
C22: 11 | D22: 6302061609840003 | E22: HENDRI WIJAYA PUTRA
C23: 12 | D23: 6303011104960001 | E23: ZAINUDIN
... C175: 164 | D175: 6371040212850004 | E175: FUADI
C176: 165 | D176: 6.3710404e+15 | E176: SUBHAN NOR
C177: 166 | D177: 6371040609010002 | E177: MUHAMMAD RAFI
C178: 167 | D178: 6371041908940005 | E178: GUSTI DERRY SETIA BUDI
C179: 168 | D179: 6371051701030004 | E179: RAHMAD ASHARI
C180: 169 | D180: 6371053005970003 | E180: MUHAMMAD FATURRAHMAN
C181: 170 | D181: 6372020104900004 | E181: ASPIRIYANI
C182: 171 | D182: 6372020107680151 | E182: ARIEF RAHMAN
C183: 172 | D183: 6372020204030001 | E183: H. AHMAD FAUZI
C184: 173 | D184: 6372020212770007 | E184: WISNU PRADES ISTIADI
C185: 174 | D185: 6372020312830001 | E185: HENDRY
C186: 175 | D186: 6372020405860001 | E186: M.RAMADHANI
C187: 176 | D187: 6372020407840003 | E187: RUSBANI
C188: 177 | D188: 6372020412760002 | E188: MIRZA KRINOVITA
... C277: 266 | D277: 6372040101880003 | E277: RITNO ADITYA
E279: Banjarbaru, Januari 2025
E280: Kepala Satuan Polisi Pamong Praja
E284: HIDAYATURAHMAN, S.Sos, M.Si.
E285: Pembina Utama Muda
E286: NIP. 19700815 199003 1 002

Sheet APARATUR
B1: PEMERINTAH KOTA BANJARBARU
B2: SATUAN POLISI PAMONG PRAJA
B3: Alamat : Jl. Pangeran Antasari No. 7 Banjarbaru Kalimantan Selatan
C4: Website : Satpolpp.banjarbarukota.go.id – Email : admin@satpolpp.banjarbarukota.go.id
A6: APARATUR PEMADAM KEBAKARAN YANG MEMENUHI STANDAR KUALIFIKASI PEMADAM
A7: PERATURAN MENTERI DALAM NEGERI NO. 16 TAHUN 2009 TENTANG STANDAR KUALIFIKASI APARATUR PEMADAM KEBAKARAN
B8: UPT PEMADAM KEBAKARAN DAN PENYELAMATAN KOTA BANJARBARU
B10: NO | C10: NAMA | G10: SERTIFIKAT KOMPETENSI | J10: TANDA TANGAN SERTIFIKAT | M10: NO REGISTRASI | Q10: TAHUN DIKLAT
B11: 1 | C11: SYAFRULLAH, S.Sos, M.Si. | G11: PEMADAM 1 | J11: DITJEN BINA ADWIL KEMENDAGRI | M11: P.157/116/TU/DAMKAR/MPBK/2024 | Q11: 2024
B12: 2 | C12: ADE SUSANTO | G12: PEMADAM 1 | J12: DITJEN BINA ADWIL KEMENDAGRI | M12: P.3/578/TU/SDV/MPBK/2022 | Q12: 2022
B13: 3 | C13: RANU WIBOWO | G13: PEMADAM 1 | J13: DITJEN BINA ADWIL KEMENDAGRI | M13: P.25/240/TU/SDV/MPBK/2022 | Q13: 2022
B14: 4 | C14: IMAM KASTALANI | G14: PEMADAM 1 | J14: DITJEN BINA ADWIL KEMENDAGRI | M14: P.22/238/TU/DAMKAR/MPBK/2024 | Q14: 2024
B15: 5 | C15: MISLADIN | G15: PEMADAM 1 | J15: DITJEN BINA ADWIL KEMENDAGRI | M15: P.57/238/TU/DAMKAR/MPBK/2024 | Q15: 2024
B16: 6 | C16: AGUS BUDIANTO | G16: PEMADAM 1 | J16: DITJEN BINA ADWIL KEMENDAGRI | M16: P.77/238/TU/DAMKAR/MPBK/2024 | Q16: 2024
B17: 7 | C17: BUDI ADI | G17: PEMADAM 1 | J17: DITJEN BINA ADWIL KEMENDAGRI | M17: P.82/238/TU/DAMKAR/MPBK/2024 | Q17: 2024
K19: Banjarbaru, Januari 2025
K20: Kepala Satuan Polisi Pamong Praja
K24: HIDAYATURAHMAN, S.Sos, M.Si.
K25: Pembina Utama Muda
K26: NIP. 19700815 199003 1 002

Sheet JUMLAH KAPASITAS
B1: PEMERINTAH KOTA BANJARBARU
B2: SATUAN POLISI PAMONG PRAJA
B3: Alamat : Jl. Pangeran Antasari No. 7 Banjarbaru Kalimantan Selatan
C4: Website : Satpolpp.banjarbarukota.go.id – Email : admin@satpolpp.banjarbarukota.go.id
A6: JUMLAH PENINGKATAN KAPASITAS APARATUR PEMADAM KEBAKARAN
B9: NO | C9: NAMA | G9: SERTIFIKAT KOMPETENSI | J9: TANDA TANGAN SERTIFIKAT | M9: NO REGISTRASI | Q9: TAHUN DIKLAT
B10: 1 | C10: SYAFRULLAH, S.Sos, M.Si. | G10: PEMADAM 1 | J10: DITJEN BINA ADWIL KEMENDAGRI | M10: P.157/116/TU/DAMKAR/MPBK/2024 | Q10: 2024
B11: 2 | C11: IMAM KASTALANI | G11: PEMADAM 1 | J11: DITJEN BINA ADWIL KEMENDAGRI | M11: P.22/238/TU/DAMKAR/MPBK/2024 | Q11: 2024
B12: 3 | C12: MISLADIN | G12: PEMADAM 1 | J12: DITJEN BINA ADWIL KEMENDAGRI | M12: P.57/238/TU/DAMKAR/MPBK/2024 | Q12: 2024
B13: 4 | C13: AGUS BUDIANTO | G13: PEMADAM 1 | J13: DITJEN BINA ADWIL KEMENDAGRI | M13: P.77/238/TU/DAMKAR/MPBK/2024 | Q13: 2024
B14: 5 | C14: BUDI ADI | G14: PEMADAM 1 | J14: DITJEN BINA ADWIL KEMENDAGRI | M14: P.82/238/TU/DAMKAR/MPBK/2024 | Q14: 2024
K16: Banjarbaru, Januari 2025
K17: Kepala Satuan Polisi Pamong Praja
K21: HIDAYATURAHMAN, S.Sos, M.Si.
K22: Pembina Utama Muda
K23: NIP. 19700815 199003 1 002

Sheet SAPRAS
B1: PEMERINTAH KOTA BANJARBARU
B2: SATUAN POLISI PAMONG PRAJA
B3: Alamat : Jl. Pangeran Antasari No. 7 Banjarbaru Kalimantan Selatan
C4: Website : Satpolpp.banjarbarukota.go.id – Email : admin@satpolpp.banjarbarukota.go.id
B6: JENIS SARANA PRASARANA PEMADAMAN, PENYELAMATAN DAN EVAKUASI
B7: UPT PEMADAM KEBAKARAN DAN PENYELAMATAN KOTA BANJARBARU
B9: NO | C9: JENIS SAPRAS | J9: KONDISI | O9: JUMLAH
B10: 1 | C10: Mobil Tangki Hino / Kajama 3500 Liter | J10: Baik | O10: 1 buah
B11: 2 | C11: Mobil Tangki Hino / Kajama 3500 Liter | J11: Baik | O11: 1 buah
B12: 3 | C12: Mobil Tangki Hino / Kajama 4000 Liter | J12: Baik | O12: 1 buah
B13: 4 | C13: Mobil Tangki Hino / Kajama 8000 Liter | J13: Baik | O13: 1 buah
B14: 5 | C14: Mobil Rescue Toyota Hilux / Kajama | J14: Baik | O14: 1 buah
B15: 6 | C15: Mobil Tangki Toyota / Gajah / Ton 2 | J15: Tidak Baik | O15: 1 buah
B16: 7 | C16: Mobil Tangki Hino Duetro / Ton 7 | J16: Baik | O16: 1 buah
B17: 8 | C17: Mobil Mesin Pompa Isuzu / 50 / Ton 3 | J17: Baik | O17: 1 buah
B18: 9 | C18: Mobil Mesin Pompa Isuzu / Naruto / Ton 4 | J18: Baik | O18: 1 buah
B19: 10 | C19: Sepeda Motor Honda Vario 160 | J19: Baik | O19: 1 buah
B20: 11 | C20: Tabung Apar | J20: Baik | O20: 7 buah
L23: Banjarbaru, Januari 2025
L24: Kepala Satuan Polisi Pamong Praja
L28: HIDAYATURAHMAN, S.Sos, M.Si.
L29: Pembina Utama Muda
L30: NIP. 19700815 199003 1 002

Sheet DATA POS 
C2: PEMERINTAH KOTA BANJARBARU
C3: SATUAN POLISI PAMONG PRAJA
C4: Alamat : Jl. Pangeran Antasari No. 7 Banjarbaru Kalimantan Selatan
D5: Website : Satpolpp.banjarbarukota.go.id – Email : admin@satpolpp.banjarbarukota.go.id
B7: POS SEKTOR DAMKAR YANG DILENGKAPI SARANA PRASARANA DAMKAR, PRASARANA PENYELAMATAN DI KECAMATAN
C8: UPT PEMADAM KEBAKARAN DAN PENYELAMATAN KOTA BANJARBARU
B11: NO | C11: KECAMATAN | I11: JUMLAH POS | N11: KETERANGAN
B12: 1 | C12: Banjarbaru Selatan | I12: 1 | N12: Posko UPT Pemadam Kebakaran
M16: Banjarbaru, Januari 2024
M17: Kepala Satuan Polisi Pamong Praja
M21: HIDAYATURAHMAN, S.Sos, M.Si.
M22: Pembina Utama Muda
M23: NIP. 19700815 199003 1 002

Sheet EVAKUASI
B1: PEMERINTAH KOTA BANJARBARU
B2: SATUAN POLISI PAMONG PRAJA
B3: Alamat : Jl. Pangeran Antasari No. 7 Banjarbaru Kalimantan Selatan
B4: Website : Satpolpp.banjarbarukota.go.id – Email : admin@satpolpp.banjarbarukota.go.id
A6: JENIS LAYANAN PENYELAMATAN DAN EVAKUASI PADA KONDISI MEMBAHAYAKAN MANUSIA
A7: ( OPERASI DARURAT NON KEBAKARAN )
B8: UPT PEMADAM KEBAKARAN DAN PENYELAMATAN KOTA BANJARBARU
B10: DATA TAHUN 2024
A12: NO | B12: HARI/TGL | C12: JAM | G12: INFO VIA | H12: KEGIATAN | I12: Hewan | J12: DLL | K12: KORBAN | M12: JUMLAH | O12: PETUGAS/UNIT OPS | S12: KET
G13: TELP/RADIO | K13: MD (org) | L13: CEDERA | M13: KK | N13: JW
A14: 1 | B14: Senin, 1 Januari 2024 | C14: 08.14 s/d 08.40 Wita | G14: Antung Febriaty No Hp. 089620360379 | H14: Menindaklanjuti laporan bahwa ada ular di dapur yang beralamat Jl. Aneka Tambang Komplek Banua Permai Gg. Permai RT. 34 RW. 07 Kel. Sungai Besar Kec. Banjarbaru Selatan. Ular tidak dapat di evakuasi diperkirakan ular sudah ada tidak ada sebelum petugas datang. Petugas mengerahkan 1 Unit Ops Damkar. | I14: 1 | J14: 0 | K14: 0 | L14: 0 | M14: 0 | N14: 0 | O14: 6 orang/1 unit | S14: ular
A15: 2 | B15: Selasa, 2 Januari 2024 | C15: 05.22 s/d 06.05 Wita | G15: Rahmat Mustakim no hp. 081251283258 | H15: Menindaklanjuti laporan dari telpon via WA Kepala UPT Damkar Kota Banjarbaru mendapat laporan dari warga meminta bantuan evakuasi ular yang berada di atap dapur rumah beliau yang beralamat Jl. Bukit Barisan RT. 17 RW. 04 Kel. Sungai Ulin Kec. Banjarbaru Utara. Ular berhasil di evakuasi dan dilepasliarkan. Petugas mengerahkan 1 Unit Ops Damkar | I15: 1 | J15: 0 | K15: 0 | L15: 0 | M15: 0 | N15: 0 | O15: 4 orang/1 unit | S15: ular
A16: 3 | B16: Selasa, 2 Januari 2024 | C16: 15.28 s/d 16.25 Wita | G16: Ibu Sarmila no hp. 087728951991 | H16: Meminta bantuan evakuasi kucing dari atas pohon yang beralamat Jl. Bina Banua Praja/ Aneka Tambang (halaman /area SMKN 3 Banjarbaru) Kel. Cempaka Kec. Cempaka. Kucing berhasil di evakuasi. Petugas mengerahkan 1 Unit Ops Damkar. | I16: 1 | J16: 0 | K16: 0 | L16: 0 | M16: 0 | N16: 0 | O16: 6 orang / 1 unit | S16: kucing
A17: 4 | B17: Rabu, 3 Januari 2024 | C17: 15.28 s/d 16.25 Wita | G17: Yudi no hp. 081251087030 | H17: Menindaklanjuti laporan perihal meminta bantuan evakuasi Sarang Tawon bersarang di atas atap yang beralamat Jl. Merpati Gang Cendrawasih Rt. 03 RW. 08 No. 35 Kel. Landasan Ulin Timur Kec. Landasan Ulin. Sarang Tawon berhasil di evakuasi. Petugas mengerahkan 1 Unit Ops Damkar. | I17: 1 | J17: 0 | K17: 0 | L17: 0 | M17: 0 | N17: 0 | O17: 6 orang/1 unit | S17: Tawon
A18: 5 | B18: Kamis, 4 Januari 2024 | C18: 20.05 s/d 21.35 Wita | G18: Firmansyah no hp. 082153608119 | H18: Menindaklanjuti laporan warga perihal meminta bantuan evakuasi Sarang Tawon di atas atap yang man sudah menyengat tukang bangunan yang beralamat Jl. A. Yani Km. 33 samping SPBU 33 Kel. Loktabat Utara Kec. Banjarbaru Utara. Sarang Tawon berhasil di evakuasi dan dibersihkan. Petugas mengerahkan 1 Unit Ops Damkar. | I18: 1 | J18: 0 | K18: 0 | L18: 0 | M18: 0 | N18: 0 | O18: 6 orang/1 unit | S18: Tawon
A19: 6 | B19: Jum`at, 5 Januari 2024 | C19: 00.08 s/d 01.00 Wita | G19: Lisa No Hp. 08115237661 | H19: Menindaklanjuti warga perihal meminta bantuan evakuasi ular yang ada dirumah beliau yang beralamat Jl. Mentaos Timur RT. 04 RW. 03 Kel. Mentaos Kec. Banjarbaru Utara. Ular berhasil di evakuasi dan dilepasliarkan. Petugas mengerahkan 1 Unit Ops Damkar. | I19: 1 | J19: 0 | K19: 0 | L19: 0 | M19: 0 | N19: 0 | O19: 4 orang/1 unit | S19: ular
A20: 7 | B20: Sabtu, 6 Januari 2024 | C20: 14.59 s/d 16.00 Wita | G20: Bapak M. Iqbal Sulaity No Hp. 082157275010 | H20: Menindaklanjuti laporan warga perihal meminta bantuan evakuasi Ular dikamar tidur milik beliau yang beralamat Jl. Tambak Langsat Komplek Griya Ramania VI RT. 29 RW. 06 Kel. Syamsudinoor Kec. Landasan Ulin. Ular berhasil di evakuasi dan dilepasliarkan. Petugas mengerahkan 1 Unit Ops Damkar. | I20: 1 | J20: 0 | K20: 0 | L20: 0 | M20: 0 | N20: 0 | O20: 6 orang/1 unit | S20: ular
A21: 8 | B21: Minggu, 7 Januari 2024 | C21: 07.11 s/d 08.00 Wita | G21: Cita Permatasari | H21: Menindaklanjuti laporan warga perihal meminta bantuan evakuasi monyet liar yang meresahkan beliau. Menurut pelapor bahwa monyet tersebut mengacak acak mobil beliau yang beralamat Jl. Penggalang RT. 03 RW. 06 Kel. Mentaos Kec. Banjarbaru Utara. Monyet liar tidak berhasil di evakuasi karena pada saat petugas datang monyet liar tersebut melarikan diri. Petugas mengerahkan 1 Unit Ops Damkar. | I21: 1 | J21: 0 | K21: 0 | L21: 0 | M21: 0 | N21: 0 | O21: 4 orang/1 unit | S21: monyet
A22: 9 | B22: Minggu, 7 Januari 2024 | C22: 10.03 s/d 12.15 Wita | G22: Lurah Mentaos | H22: Menindaklanjuti laporan Lurah Mentaos ke Kepala UPT Damkar Kota Banjarbaru perihal meminta bantuan evakuasi monyet liar yang meresahkan warga dan sudah menyebabkan adanya korban gigitan monyet tersebut yang beralamat Jl. Gotong Royong RT. 04 RW. 06 Kel. Mentaos Kec. Banjarbaru Utara. Monyet liar tersebut belum berhasil ditangkap. Petugas menegerahkan 1 Unit Ops Damkar | I22: 1 | J22: 0 | K22: 0 | L22: 0 | M22: 0 | N22: 0 | O22: 6 orang/1 unit | S22: monyet
A23: 10 | B23: Senin, 8 Januari 2024 | C23: 10.57 s/d 13.30 Wita | G23: Ridhani No Hp. 082157046249 | H23: Menindaklanjuti laporan warga meminta bantuan bahwa adanya monyet liar yang meresahkan serta sudah ada yang menjadi korban sebanyak 5 orang terkena cakaran dan gigitan yang beralamat Jl. Gotong Royong, Jl. Penggalang, Jl. Gotong Royong 3 dan sekitarnya Kel. Mentaos Kec. Banjarbaru Utara. Monyet belum berhasil di evakuasi/ ditangkap. Petugas mengerahkan 1 Unit Ops Damkar. | I23: 1 | J23: 0 | K23: 0 | L23: 0 | M23: 0 | N23: 0 | O23: 9 orang/1 unit | S23: monyet
A24: 11 | B24: Selasa, 9 Januari 2024 | C24: 05.10 s/d 06.23 Wita | G24: M. Lazuardi Lukmana No Hp. 082246258349 | H24: Menindaklanjuti laporan warga perihal meminta bantuan evakuasi ular yang memasuki rumah beliau yang beralamat Jl. Berkat Mufakat RT. 14 RW. 04 Kel. Landasan Ulin Barat Kec. Liang anggang. Ular berhasil di evakuasi dan dilepasliarkan. Petugas mengerahkan 1 Unit Ops Damkar | I24: 1 | J24: 0 | K24: 0 | L24: 0 | M24: 0 | N24: 0 | O24: 4 orang/1 unit | S24: ular
A25: 12 | B25: Rabu, 10 Januari 2024 | C25: 10.48 s/d 11.10 Wita | G25: Bapak Doni | H25: Menindaklanjuti laporan warga perihal meminta bantuan evakuasi ular yang berada dihalaman rumah beliau yang beralamat Jl. Pondok Satria Jaya No. C/07 RT. 26 RW. 10 Kel. Loktabat Utara Kec. Banjarbaru Utara. Ular berhasil di evakuasi dan dilepasliarkan. Petugas mengarahkan 1 Unit Ops Damkar | I25: 1 | J25: 0 | K25: 0 | L25: 0 | M25: 0 | N25: 0 | O25: 7 orang/1 unit | S25: ular
A26: 13 | B26: Kamis, 11 Januari 2024 | C26: 00.10 s/d 01.00 Wita | G26: Tiara Cahyani No Hp. 081528649001 | H26: Menindaklanjuti laporan warga perihal meminta bantuan evakuasi kucing yang tidak bisa turun dari atap rumah yang beralamat Jl. Intan Sari Gg. Warna Sari No. 24 RT. 03 Kel. Sungai Besar Kec. Banjarbaru Selatan. Kucing berhasil di evakuasi. Petugas menegerahkan 1 Unit Ops Damkar. | I26: 1 | J26: 0 | K26: 0 | L26: 0 | M26: 0 | N26: 0 | O26: 4 orang/1 unit | S26: kucing
A27: 14 | B27: Kamis, 11 Januari 2024 | C27: 19.25 s/d 20.20 Wita | H27: Menindaklanjuti laporan warga a/n. Bapak Doni No Hp. 085754319778 perihal meminta bantuan evakuasi kucing yang tercebur ke dalam sumur yang beralamat Jl. Bukit Lentera Komplek Vila Cahaya Insan Kel. Sungai besar Kec. Banjarbaru Selatan. Kucing berhasil di evakuasi. Petugas mengerahkan 1 Unit Ops Damkar | I27: 1 | J27: 0 | K27: 0 | L27: 0 | M27: 0 | N27: 0 | O27: 6 orang/1 unit | S27: kucing
A28: 15 | B28: Jum`at, 12 Januari 2024 | C28: 06.20 s/d 07.15 Wita | G28: Galih No Hp. 085754217233 | H28: Menindaklanjuti laporan warga perihal meminta bantuan evakuasi ular yang berada didalam rumah beliau beralamat Komplek Pesona Cempaka RT. 29 RW. 02 Kel. Cempaka Kec. Cempaka. Ular berhasil di evakuasi dan dilepasliarkan. Petugas mengerahkan 1 Unit Ops Damkar. | I28: 1 | J28: 0 | K28: 0 | L28: 0 | M28: 0 | N28: 0 | O28: 4 orang/1 unit | S28: ular
A29: 16 | B29: Jum`at, 12 Januari 2024 | C29: 10.27 s/d 11.15 Wita | G29: Prayudi No Hp. 081391527744 | H29: Menindaklanjuti laporan warga meminta bantuan evakuasi monyet liar yang beralamat UPT Balai Benih Hortikultura Jl. A. Yani Km. 30, 5 Kel. Guntung Manggis Kec. Landasan Ulin. Monyet yang dilaporkan masih ada di tempat, petugas berupaya menangkap monyet tersebut namun tidak berhasil karena melarikan diri ke sebelah pagar dan menghilang dibalik komplek pemukiman warga . Petugas mengerahkan 1 Unit Ops Damkar. | I29: 1 | J29: 0 | K29: 0 | L29: 0 | M29: 0 | N29: 0 | O29: 6 orang/1 unit | S29: monyet
A30: 17 | B30: Minggu, 14 Januari 2024 | C30: 15.20 s/d 16.20 Wita | G30: Ibu Niki Budiarto No Hp. 087816118454 | H30: Menindaklanjuti warga perihal meminta bantuan evakuasi ular yang ada dipekarangan rumah beliau yang beralamat Jl. Pondok Bambu, Komplek Graha Idaman Permai RT. 19 RW. 08 Kel. Loktabat Utara Kec. Banjarbaru Utara. Ular berhasil di evakuasi dan dilepasliarkan. Petugas mengerahkan 1 Unit Ops Damkar. | I30: 1 | J30: 0 | K30: 0 | L30: 0 | M30: 0 | N30: 0 | O30: 6 orang/1 unit | S30: ular
A31: 18 | B31: Selasa, 16 Januari 2024 | C31: 00.25 s/d 01.30 Wita | G31: Ibu Desy No Hp. 0887435879065 | H31: Menindaklanjuti laporan warrga perihal meminta bantuan evakuasi ular di ruang makan rumah beliau yang beralamat Jl. A. Yani Gg. Gelatik No. 21 RT. 03 RW. 08 Kel. Landasan Ulin Timur Kec. Landasan Ulin. Ular berhasil di evakuasi dan dilepasliarkan. Petugas mengerahkan 1 unit Ops Damkar. | I31: 1 | J31: 0 | K31: 0 | L31: 0 | M31: 0 | N31: 0 | O31: 6 orang/1 unit | S31: ular
A32: 19 | B32: Selasa, 16 Januari 2024 | C32: 17.21 s/d 18.10 Wita | G32: Fauzan No Hp. 081255481771 | H32: Menindaklanjuti laporan warga perihal meminta bantuan evakuasi yang terkurung di ruko awiyah lantai 2 yang beralamat di Jl. Panglima Batur Timur Kel. Komet Kec. Banjarbaru Utara. Kucing berhasil di evakuasi dengan selamat. Petugas mengerahkan 1 unit Ops Damkar. | I32: 1 | J32: 0 | K32: 0 | L32: 0 | M32: 0 | N32: 0 | O32: 6 orang/1 unit | S32: kucing
A33: 20 | B33: Rabu, 17 Januari 2024 | C33: 09.06 s/d 09.57 Wita | G33: Sugi No Hp. 082252389189 | H33: Menindaklanjuti laporan warga perihal meminta bantuan evakuasi ular yang berada di rumah beliau yang beralamat Jl. Guntung Paring Komplek Graha Mandiri Asri RT. 08 No. 25 Kel. Guntung Manggis Kec. Landasan Ulin. Ular berhasil di evakuasi dan dilepasliarkan. Petugas mengerahkan 1 Unit Ops Damkar. | I33: 1 | J33: 0 | K33: 0 | L33: 0 | M33: 0 | N33: 0 | O33: 6 orang / 1 unit | S33: ular
A34: 21 | B34: Kamis, 18 Januari 2024 | C34: 16.50 s/d 17.30 Wita | G34: Bapak Yauma Nugraha no hp. 082220007779 | H34: Menindaklanjuti laporan warga perihal meminta bantuan evakuasi biawak yang terjebak disamping rumah milik beliau yang beralamat Jl. Kasturi RT. 01 RW. 02 Kel. Guntung Paikat Kec. Banjarbaru Selatan. Dilokasi petugas melakukan pencarian di samping rumah bapak yauma nugraha tidak ada ditemukan biawak. diperkirakan biawak sudah melarikan diri. Petugas mengerahkan 1 Unit Ops Damkar. | I34: 1 | J34: 0 | K34: 0 | L34: 0 | M34: 0 | N34: 0 | O34: 6 orang/1 unit | S34: biawak
A35: 22 | B35: Jum`at, 19 Januari 2024 | C35: 08.10 s/d 09.15 Wita | G35: Bapak Suparno No Hp. 08990036099 | H35: Menindaklanjuti laporan warga perihal meminta bantuan evakuasi ular yang berada dikandang burung milik beliau yang beralamat Komp. Bukit Lestari IV No. 31 RT. 33 RW. 07 Kel. Sungai Besar Kec. Banjarbaru Selatan. Ular berhasil dievakuasi dan dilepasliarkan ada 2 ular. Petugas mengerahkan 1 Unit Ops Damkar. | I35: 1 | J35: 0 | K35: 0 | L35: 0 | M35: 0 | N35: 0 | O35: 6 orang/1 unit | S35: ular
A36: 23 | B36: Sabtu, 20 Januari 2024 | C36: 09.14 s/d 10.50 Wita | G36: Ibu Sari No Hp. 082350377068 | H36: Menindaklanjuti laporan warga perihal meminta bantuan evakuasi ular yang berada di dalam kandang ayam milik beliau yang beralamat Jl. Padang Golf RT. 12 RW. 03 No. 19 Kel. Syamsudinoor Kec. Landasan Ulin. Ular berhasil di evakuasi dan dilepasliarkan. Petugas mengerahkan 1 Unit Ops Damkar. | I36: 1 | J36: 0 | K36: 0 | L36: 0 | M36: 0 | N36: 0 | O36: 6 orang/1 unit | S36: ular
A37: 24 | B37: Minggu, 21 Januari 2024 | C37: 06.00 s/d 07.00 Wita | G37: Arif Ariandi No Hp. 08121515127 | H37: Menindaklanjuti laporan warga perihal meminta bantuan evakuasi ular yang berada dirumah beliau yang beralamat Jl. Cempaka Sari Jalur 22 RT. 34 RW. 07 Kel. Sungai Besar Kec. Banjarbaru selatan. Ular berhasil di evakuasi dan dilepasliarkan. Petugas mengerahkan 1 Unit Ops Damkar. | I37: 1 | J37: 0 | K37: 0 | L37: 0 | M37: 0 | N37: 0 | O37: 4 orang/1 unit | S37: ular
A38: 25 | B38: Minggu, 21 Januari 2024 | C38: 20.01 s/d 20.30 Wita | G38: Faisal Rahman No Hp. 081250003888 | H38: Menindaklanjuti laporan warga meminta bantuan evakuasi ular yang berada dihalaman rumah yang beralamat Jl. Al-Jafrie RT. 13 RW. 03 Kel. Kemuning Kec. Banjarbaru Selatan. Ular berhasil di evakuasi dan dilepasliarkan. Petugas mengerahkan 1 Unit Ops Damkar. | I38: 1 | J38: 0 | K38: 0 | L38: 0 | M38: 0 | N38: 0 | O38: 6 orang/1 unit | S38: ular
A39: 26 | B39: Senin, 22 Januari 2024 | C39: 20.02 s/d 21.15 Wita | G39: Bapak M. Hadriani No Hp. 081414099117 | H39: Menindaklanjuti laporan warga perihal meminta bantuan evakuasi sarang tawon di atas atap rumah beliau yang beralamat Jl. Purnawirawan Komp. Lambung Mangkurat Regency Blok H 2 No. 15 Kel. Palam Kec. Cempaka. Sarang tawon berhasil di musnahkan dan dibersihkan. Petugas mengerahkan 1 Unit Ops Damkar. | I39: 1 | J39: 0 | K39: 0 | L39: 0 | M39: 0 | N39: 0 | O39: 6 orang/1 unit | S39: tawon
... A446: 433 | B446: Minggu, 29 Desember 2024 | C446: 21.52 s/d 23.05 Wita | G446: Eko No Hp. 081649338978 | H446: Menindaklanjuti laporan warga perihal meminta bantua evakuasi ular yang berada di atas kerangka atap rumah beralamat Jl. Caraka Komp. CMP No J 12 RT. 12 RW. 10 Kel. Landasan Ulin Utara Kec. Liang Aggang. Petugas berhasil mengevakuasi ular tersebut dan dilepasliarkan. Petugas mengerahkan 1Unit Ops Damkar Mobil Hilux Kajama Rescue. | I446: 1 | J446: 0 | K446: 0 | L446: 0 | M446: 0 | N446: 0 | O446: 7 orang/1 unit | S446: ular
H449: Kepala Satuan Polisi Pamong Praja
H450: Banjarbaru, Januari 2025
H454: HIDAYATURAHMAN, S.Sos, M.Si.
...

Sheet Sheet1
A3: Jumlah Evakuasi Hewan
B4: Ular | C4: Kucing | D4: Lebah | E4: Tawon | F4: Musang | G4: Anjing | H4: Monyet | I4: Biawak | J4: Burung | K4: Tikus | L4: Cicak | M4: Senggung | N4: Bekantan | O4: Jumlah
A5: Januari | B5: 20 | C5: 6 | D5: 1 | E5: 4 | F5: 0 | G5: 0 | H5: 4 | I5: 1 | J5: 0 | K5: 0 | L5: 0 | M5: 0 | N5: 0 | O5: =SUM(B5:N5) -> 36
A6: Februari | B6: 23 | C6: 3 | D6: 1 | E6: 3 | F6: 0 | G6: 0 | H6: 1 | I6: 0 | J6: 0 | K6: 0 | L6: 0 | M6: 0 | N6: 0 | O6: =SUM(B6:N6) -> 31
A7: Maret | B7: 16 | C7: 3 | D7: 4 | E7: 1 | F7: 0 | G7: 2 | H7: 2 | I7: 2 | J7: 0 | K7: 0 | L7: 1 | M7: 0 | N7: 0 | O7: =SUM(B7:N7) -> 31
A8: April | B8: 20 | C8: 1 | D8: 4 | E8: 0 | F8: 0 | G8: 4 | H8: 2 | I8: 0 | J8: 1 | K8: 0 | L8: 0 | M8: 0 | N8: 0 | O8: =SUM(B8:N8) -> 32
A9: Mei | B9: 25 | C9: 3 | D9: 2 | E9: 1 | F9: 1 | G9: 2 | H9: 2 | I9: 1 | J9: 0 | K9: 0 | L9: 0 | M9: 0 | N9: 0 | O9: =SUM(B9:N9) -> 37
A10: Juni | B10: 22 | C10: 5 | D10: 3 | E10: 0 | F10: 0 | G10: 0 | H10: 2 | I10: 0 | J10: 0 | K10: 0 | L10: 0 | M10: 0 | N10: 0 | O10: =SUM(B10:N10) -> 32
A11: Juli | B11: 21 | C11: 6 | D11: 0 | E11: 1 | F11: 0 | G11: 4 | H11: 1 | I11: 0 | J11: 0 | K11: 0 | L11: 0 | M11: 0 | N11: 0 | O11: =SUM(B11:N11) -> 33
A12: Agustus | B12: 23 | C12: 6 | D12: 2 | E12: 1 | F12: 3 | G12: 2 | H12: 0 | I12: 0 | J12: 0 | K12: 0 | L12: 0 | M12: 0 | N12: 1 | O12: =SUM(B12:N12) -> 38
A13: September | B13: 18 | C13: 4 | D13: 2 | E13: 1 | F13: 0 | G13: 3 | H13: 1 | I13: 1 | J13: 0 | K13: 0 | L13: 0 | M13: 0 | N13: 0 | O13: =SUM(B13:N13) -> 30
A14: Oktober | B14: 29 | C14: 2 | D14: 2 | E14: 2 | F14: 0 | G14: 1 | H14: 1 | I14: 0 | J14: 0 | K14: 0 | L14: 0 | M14: 0 | N14: 0 | O14: =SUM(B14:N14) -> 37
A15: November | B15: 13 | C15: 6 | D15: 1 | E15: 0 | F15: 1 | G15: 0 | H15: 0 | I15: 1 | J15: 0 | K15: 0 | L15: 0 | M15: 0 | N15: 0 | O15: =SUM(B15:N15) -> 22
A16: Desember | B16: 10 | C16: 2 | D16: 1 | E16: 0 | F16: 1 | G16: 3 | H16: 0 | I16: 0 | J16: 0 | K16: 1 | L16: 0 | M16: 1 | N16: 0 | O16: =SUM(B16:N16) -> 19
A18: Jumlah | B18: =SUM(B5:B17) -> 240 | C18: =SUM(C5:C17) -> 47 | D18: =SUM(D5:D17) -> 23 | E18: =SUM(E5:E17) -> 14 | F18: =SUM(F5:F17) -> 6 | G18: =SUM(G5:G17) -> 21 | H18: =SUM(H5:H17) -> 16 | I18: =SUM(I5:I17) -> 6 | ... N18: =SUM(N5:N17) -> 1 | O18: =SUM(B18:N18) -> 378
A21: Jumlah Evakuasi lain-lain Non Hewan
B22: Pohon | C22: Cincin | D22: Handphone | E22: Pintu Rumah | F22: Kunci Sepeda Motor | G22: Mobil | H22: Neon Box | I22: Banjir | J22: Pagar Tembok Runtuh | K22: Penyemprotan Jalan | L22: Drone | M22: Orang Tertimbun Longsor | N22: Orang Tenggelam | O22: Orang Tercebur Sumur | P22: Orang Terjepit Tembok | Q22: Orang Kecelakan | R22: Lansia | S22: Mesin Pompa Air | T22: Jumlah
A23: Januari | B23: 0 | C23: 0 | D23: 0 | E23: 0 | F23: 0 | G23: 0 | H23: 0 | I23: 0 | J23: 0 | K23: 0 | L23: 0 | M23: 0 | N23: 0 | O23: 0 | P23: 0 | Q23: 0 | R23: 0 | S23: 0 | T23: =SUM(B23:S23) -> 0
A24: Februari | B24: 1 | C24: 1 | D24: 0 | E24: 0 | F24: 0 | G24: 0 | H24: 0 | I24: 0 | J24: 0 | K24: 0 | L24: 0 | M24: 0 | N24: 0 | O24: 0 | P24: 0 | Q24: 0 | R24: 0 | S24: 0 | T24: =SUM(B24:S24) -> 2
A25: Maret | B25: 3 | C25: 2 | D25: 0 | E25: 0 | F25: 0 | G25: 0 | H25: 0 | I25: 1 | J25: 0 | K25: 0 | L25: 0 | M25: 0 | N25: 0 | O25: 0 | P25: 0 | Q25: 0 | R25: 0 | S25: 0 | T25: =SUM(B25:S25) -> 6
A26: April | B26: 0 | C26: 2 | D26: 0 | E26: 0 | F26: 0 | G26: 0 | H26: 0 | I26: 0 | J26: 0 | K26: 0 | L26: 1 | M26: 0 | N26: 0 | O26: 0 | P26: 1 | Q26: 0 | R26: 0 | S26: 0 | T26: =SUM(B26:S26) -> 4
A27: Mei | B27: 0 | C27: 3 | D27: 1 | E27: 0 | F27: 0 | G27: 0 | H27: 0 | I27: 0 | J27: 0 | K27: 0 | L27: 0 | M27: 0 | N27: 0 | O27: 0 | P27: 0 | Q27: 0 | R27: 0 | S27: 0 | T27: =SUM(B27:S27) -> 4
A28: Juni | B28: 0 | C28: 2 | D28: 0 | E28: 0 | F28: 0 | G28: 3 | H28: 1 | I28: 0 | J28: 0 | K28: 1 | L28: 0 | M28: 0 | N28: 1 | O28: 0 | P28: 0 | Q28: 0 | R28: 0 | S28: 0 | T28: =SUM(B28:S28) -> 8
A29: Juli | B29: 1 | C29: 1 | D29: 0 | E29: 0 | F29: 0 | G29: 0 | H29: 0 | I29: 0 | J29: 0 | K29: 1 | L29: 0 | M29: 0 | N29: 0 | O29: 0 | P29: 0 | Q29: 0 | R29: 0 | S29: 0 | T29: =SUM(B29:S29) -> 3
A30: Agustus | B30: 0 | C30: 0 | D30: 0 | E30: 0 | F30: 1 | G30: 1 | H30: 0 | I30: 0 | J30: 0 | K30: 2 | L30: 0 | M30: 0 | N30: 0 | O30: 1 | P30: 0 | Q30: 0 | R30: 0 | S30: 0 | T30: =SUM(B30:S30) -> 5
A31: September | B31: 1 | C31: 1 | D31: 1 | E31: 0 | F31: 0 | G31: 1 | H31: 0 | I31: 0 | J31: 0 | K31: 1 | L31: 0 | M31: 0 | N31: 0 | O31: 0 | P31: 0 | Q31: 0 | R31: 1 | S31: 1 | T31: =SUM(B31:S31) -> 7
A32: Oktober | B32: 0 | C32: 3 | D32: 0 | E32: 1 | F32: 1 | G32: 0 | H32: 0 | I32: 0 | J32: 1 | K32: 0 | L32: 0 | M32: 1 | N32: 0 | O32: 0 | P32: 0 | Q32: 0 | R32: 0 | S32: 0 | T32: =SUM(B32:S32) -> 7
A33: November | B33: 2 | C33: 1 | D33: 0 | E33: 0 | F33: 0 | G33: 0 | H33: 0 | I33: 0 | J33: 0 | K33: 0 | L33: 0 | M33: 0 | N33: 0 | O33: 0 | P33: 0 | Q33: 1 | R33: 0 | S33: 0 | T33: =SUM(B33:S33) -> 4
A34: Desember | B34: 3 | C34: 0 | D34: 0 | E34: 0 | F34: 0 | G34: 1 | H34: 0 | I34: 0 | J34: 0 | K34: 1 | L34: 0 | M34: 0 | N34: 0 | O34: 0 | P34: 0 | Q34: 0 | R34: 0 | S34: 0 | T34: =SUM(B34:S34) -> 5
B36: =SUM(B23:B35) -> 11 | C36: =SUM(C23:C35) -> 16 | D36: =SUM(D23:D35) -> 2 | E36: =SUM(E23:E35) -> 1 | F36: =SUM(F23:F35) -> 2 | G36: =SUM(G23:G35) -> 6 | H36: =SUM(H23:H35) -> 1 | I36: =SUM(I23:I35) -> 1 | ... T36: =SUM(T23:T35) -> 55
B38: Jumlah Kegiatan | C38: Hewan | D38: DLL | E38: KORBAN | H38: Cedera
E39: MD (org)
B40: =O18+T36 -> 433 | C40: =O18 -> 378 | D40: =T36 -> 55 | E40: =SUM(EVAKUASI!K14:K446) -> 2 | H40: =SUM(EVAKUASI!L14:L446) -> 1

Sheet RESPONSE TIME
B2: PEMERINTAH KOTA BANJARBARU
B3: SATUAN POLISI PAMONG PRAJA
B4: Alamat : Jl. Pangeran Antasari No. 7 Banjarbaru Kalimantan Selatan
B5: Website : Satpolpp.banjarbarukota.go.id – Email : admin@satpolpp.banjarbarukota.go.id
A7: RATA-RATA WAKTU TANGGAP (RESPONSE TIME) PENANGANAN KEBAKARAN
A8: UPT PEMADAM KEBAKARAN DAN PENYELAMATAN KOTA BANJARBARU
A9: TAHUN 2024
A12: NO | B12: HARI/TGL | C12: JAM | D12: JAM | H12: INFO VIA | I12: KEGIATAN | J12: YG TERBAKAR | L12: Hewan | M12: DLL | N12: KORBAN | P12: JUMLAH | R12: PENYEBABNYA | S12: PETUGAS/UNIT OPS | W12: RESPONSE TIME | X12: SATUAN | Y12: KET
C13: LAPORAN DITERIMA | H13: TELP/RADIO | J13: LAHAN | K13: BANGUNAN | N13: MD (org) | O13: CEDERA | P13: KK | Q13: JW | X13: JAM
A14: 1 | B14: Kamis, 1 Februari 2024 | C14: 14.20 Wita | D14: 14.28 s/d 16.10 Wita | H14: Ricky No Hp. 0819098000201 | I14: Menindaklanjuti laporan warga perihal telah terjadi kebakaran Bangunan di SDN 2 Kemuning yang beralamat di Jl. Kartini RT. 21 RW. 05 Kel. Kemuning Kec. Banjarbaru Selatan. Laporan di terima pukul 14.20 Wita petugas pun langsung bergerak ke lokasi terjadinya kebakaran. Api berhasil dipadamkan. Akibat yang ditimbulkan 4 buah Rumah Dinas Sekolah dan 1 buah gudang terbakar. 2 buah rumah rusak berat a/n. Ibu Rahmi dan Anoor. 2 buah rusak ringan dengan keadaan kosong. Asal api belum diketahui dan masih dalam penyelidikan pihak yang berwajib. Kerugian diperkirakan kurang lebih 300 Jutaan. Petugas mengerahkan 2 Unit Ops Damkar | J14: 0 | K14: 4 | L14: 0 | M14: 0 | N14: 0 | O14: 0 | P14: 1 | Q14: 1 | R14: belum diketahui | S14: 12 orang/2 unit | W14: 14 | X14: Menit
A15: 2 | B15: Kamis, 08 Februari 2024 | C15: 22.02 Wita | D15: 22.11 s/d 23.30 Wita | H15: Ibu Ida No Hp. 083836466700 | I15: Menindaklanjuti Laporan tentang adanya kebakaran bangunan di Komplek Perumahan PLN Wilayah Kalselteng Jl. Panglima Batur RT. 01 RW.06 No. A 14, 15, 16 Kel. Mentaos Kec. Banjarbaru Utara. Laporan diterima pada pukul 22.02 Wita, petugas langsung meluncur kelokasi kejadian dan dilokasi petugas melakukan pemadaman, pendinginan dan pendataan. diketahui akibat kebakaran 3 buah Rumah terbakar dengan rusak berat. 2 rumah tanpa penghuni. 1 buah rumah berpenghuni a/n. Thoha Solihin 1 KK 4 Jiwa. Kerugian bangunan kurang lebih 400 Juta Rupiah. Petugas mengerahkan 2 Unit Ops Damkar. | J15: 0 | K15: 3 | L15: 0 | M15: 0 | N15: 0 | O15: 0 | P15: 1 | Q15: 4 | R15: belum diketahui | S15: 14 orang/2 unit | W15: 14 | X15: Menit
A16: 3 | B16: Senin, 19 Februari 2024 | C16: 18.57 Wita | D16: 19.08 s/d Selesai Wita | H16: Bapak M. Subakhi No Hp. 081348107468 | I16: Menindaklanjuti laporan warga perihal telah terjadi kebakaran bangunan yang beralamat Jl. Gotong Royong Gg. Manggis RT. 16 RW. 04 Kel. Syamsudin Noor Kec. Landasan Ulin. Laporan diterima pada Pukul 18.57 Wita Petugas langsung meluncur ke lokasi kejadian. Di Lokasi petugas melakukan Pemadaman, Pendingina dan Pendataan. Terdampak kebakaran 1 Buah Rumah beserta Warung A/n. Pitrus Fatri (pemilik rumah) dihuni 1 KK 2 Jiwa. Penyebab kebakaran masih dalam penyelidikan pihak berwajib. Kerugian kurang lebih 300 juta. Petugas mengerahkan 1 Unit Ops Damkar. | J16: 0 | K16: 1 | L16: 0 | M16: 0 | N16: 0 | O16: 0 | P16: 1 | Q16: 2 | R16: belum diketahui | S16: 13 orang/1 unit | W16: 14 | X16: Menit
A17: 4 | B17: Rabu, 28 Februari 2024 | C17: 01.45Wita | D17: 02.00 s/d 03.15 Wita | H17: Via Grup WA Emergency Banjarbaru | I17: Menindaklanjuti laporan grup emergency banjarbaru bahwa telah terjadi kebakaran bangunan kandang ayam. Kondisi kandang ayam keadaan kosong baru panen uk. P : 50m L : 5m yang beralamat Jl. Sumber Makmur 1 RT. 07 RW. 04 Kel. Landasan Ulin Utara Kec. Liang Anggang. Pemilik an. Mukhtar Supian. Asal api masih dalam proses penyelidikan Kepolisian. Kondisi bangunan habis terbakar terbuat dari bahan kayu. Kerugian diperkirakan kurang lebih 50 juta rupiah. Petugas mengerahkan 2 Unit Ops Damkar | J17: 0 | K17: 1 | L17: 0 | M17: 0 | N17: 0 | O17: 0 | P17: 0 | Q17: 0 | R17: belum diketahui | S17: 11 orang/2 unit | W17: 15 | X17: Menit | Y17: kandang ayam
A18: 5 | B18: Sabtu, 16 Maret 2024 | C18: 13.07 Wita | D18: 13.16 s/d 15.50 Wita | H18: Via Grup WA Emergency Banjarbaru | I18: Menidaklanjuti laporan dari Grup Emergency Banjarbaru bahwa telah terjadi kebakaran bangunan padat penduduk beralamat Jl. Mistarcokrokusumo Kel. Cempaka Kec. Cempaka. Laporan diterima pada Pukul 13.07 Wita petugas lansung meluncur ke lokasi keajadian. Dilokasi api membesar Petugas melakukan penyemprotan mengerahkan 3 Unit Ops Damkar. Api berhasil dipadamkan dan petugas melakukan pendingian dan pendataan. Data rumah yang terdampak RT. 06 RW. 02. 1. Abdul Fatah 6 Jiwa Rusak Ringan, 2. Zainul Falihi 5 Jiwa Rusak Berat, 3. Hj. Nurul Khair Ikhrom 6 Jiwa Rusak Berat 3. Hj. Nurhayani dan Winda 5 Jiwa Rusak Berat 6. Khalifah 4 Jiwa Rusak Ringan 5. Sarniah dan M. Tarmiji 7 Jiwa Rusak Berat, Masrani 1 Jiwa Rusak Berat, 8 Raudah 1 Jiwa Rusak Sedang, 9 Musholla Rusak Sedang. Data Rumah Terdampak RT. 23 RW. 02. 1 Rabiatul Adiwiyah 4 Jiwa Rusak Berat, 2. Akhmad 7 Jiwa Rusak Berat, 3. Samlani 5 Jiwa Rusak Berat, 4. Hj. Adaniah 3 Jiwa Rusak Berat, 5. Hapsah 4 Jiwa Rusak Sedang, 6. M. Kusairi 8 Jiwa Rusak Sedang, 7. Alm. Fullah Rumah Kosong Rusak Berat, 8. Nuraini 4 Jiwa Rusak Berat. Jumlah 17 buah rumah yang terdampak dan kerugian diperkirakan kurang lebih 1 Miliyar. Asal api masih dalam proses penyelidikan Kepolisian. | J18: 0 | K18: 17 | L18: 0 | M18: 0 | N18: 0 | O18: 0 | P18: 16 | Q18: 70 | R18: belum diketahui | S18: 14 orang/2 unit | W18: 15 | X18: Menit
A19: 6 | B19: Minggu, 24 Maret 2024 | C19: 19.15 Wita | D19: 19.30 s/d 21.00 Wita | H19: Via Grup WA Emergency Banjarbaru | I19: Menindaklajuti laporan Grup WA Emergency Banjarbaru bahwa telah terjadi kebakaran bangunan di daerah golf beralamat Jl. Pelita 3 RT. 03 RW. 03 Kel. Landasan Ulin Utara Kec. Liang Anggang. Petugas menerima laporan 19.25 Wita. Petugas langsung meluncur ke lokasi kejadian. Terdampak 2 buah rumah 1. a/n. Sugeng 4 Jiwa. 2. a/n. Siti 2 Jiwa. Asal api masih dalam tahap penyelidikan kepolisian. Petugas mengerahkan 3 Unit Ops Damkar. | J19: 0 | K19: 2 | L19: 0 | M19: 0 | N19: 0 | O19: 0 | P19: 2 | Q19: 5 | R19: belum diketahui | S19: 13 orang/3 unit | W19: 15 | X19: Menit
A20: 7 | B20: Senin, 8 April 2024 | C20: 18.37 Wita | D20: 19.30 s/d 21.00 Wita | H20: via grup emergency | I20: Menindaklanjuti laporan via grup WA Emergency Banjarbaru telah terjadi kebakaran bangunan dan Laporan diterima pada pukul 23.28 Wita yang beralamat Jl. Pumpung RT. 30 RW. 10 Kel. Sungai Tiung Kec. Cempaka. Petugas menuju lokasi kejadian dan Api berhasil dipadamkan. Terdampak 2 buah rumah rusak ringan sekitar 20%. Pemilik rumah : 1. Ibu Winda Arika (Ketua RT) dan Muhammad Rijali (1 KK 2 Jiwa) 2. Ibu Jurmiah dan Dicky Irawan (1 KK 2 Jiwa) . Petugas mengerahkan 2 Unit Ops Damkar. | J20: 0 | K20: 2 | L20: 0 | M20: 0 | N20: 0 | O20: 0 | P20: 2 | Q20: 4 | R20: belum diketahui | S20: 8 orang/2 unit | W20: 15 | X20: Menit
A21: 8 | B21: Jum`at, 19 april April 2024 | C21: 18.38 Wita | D21: 18.50 s/d 19.40 Wita | H21: via grup emergency | I21: Menindaklanjuti laporan dari Grup WA Emergency Banjarbaru telah terjadi kebakaran pada pukul 18.38 Wita beralamat Jl. A. Yani Samping Radar Banjarmasin Kel. Landasan Ulin Timur Kec. Landasan Ulin. Petugas langsung menuju lokasi terdampak 1 buah lapak barang bekas ukuran 2 x 3 Meter yang terbakar. Petugas mengerahkan 1 Unit Ops damkar | J21: 0 | K21: 1 | L21: 0 | M21: 0 | N21: 0 | O21: 0 | P21: 0 | Q21: 0 | R21: belum diketahui | S21: 6 orang/1 unit | W21: 15 | X21: Menit | Y21: lapak
A22: 9 | B22: Rabu, 24 April 2024 | C22: 04.51 Wita | D22: 05.05 s/d 06.30 Wita | H22: Bapak Muhammad Syarkawi No Hp. 081649770559 | I22: Menindaklanjuti laporan warga perihal telah terjadi kebakaran bangunan pada pukul 04.51 Wita beralamat Jl. Mistarcokrokusumo RT. 01 RW. 01 Kel. Bangkal Kec. Cempaka. Terdampak 1 buah rumah terbakar habis an. Bapak Agus (1 KK 2 Jiwa) rumah tersebut berdampingan dengan bangsau atau tempat pengolahan kayu Bapak Taufik. Petugas mengerahkan 2 Unit Ops Damkar. | J22: 0 | K22: 1 | L22: 0 | M22: 0 | N22: 0 | O22: 0 | P22: 1 | Q22: 2 | R22: belum diketahui | S22: 5 orang/ 2 unit | W22: 14 | X22: Menit
A23: 10 | B23: Rabu, 8 Mei 2024 | C23: 18.02 Wita | D23: 18.09 s/d 18.50 Wita | H23: Bapak Najuari No Hp. 08386625264 | I23: Menindaklanjuti laporan warga pada Pukul 18.02 Wita perihal telah terjadi kebakaran bangunan yang beralamat Jl. A. Yani Gg. Bersama RT. 03 RW. 06 Kel. Komet Kec. Banjarbaru Utara. 1 buah spring bed serta beberapa pakaian terbakar. Petugas berhasil memadamkan api tersebut. Terdampak 1 KK 3 Jiwa ( Ibu Maryati). Kerugian berupa 1 buah spring bed, pakaian, 1 lemari. Awal api diperkirakan dari konsleting listrik. Petugas mengerahkan 1 Unit Ops Damkar. | J23: 0 | K23: 1 | L23: 0 | M23: 0 | N23: 0 | O23: 0 | P23: 1 | Q23: 3 | R23: belum diketahui | S23: 7 orang/1 unit | W23: 14 | X23: Menit
A24: 11 | B24: Jum`at, 24 Mei 2024 | C24: 02.05 Wita | D24: 02.15 s/d 03.20 Wita | H24: Abu Gifari Via Grup Emergency Banjarbaru No Hp. 085348062161 | I24: Menindaklanjuti laporan warga alamat Jl. A. Yani Km. 35 RT. 03 Kel. Komet Kec. Banjarbaru Utara. Laporan diterima pada Pukul 02.05 Wita petugas langsung menuju lokasi terjadinya kebakaran. Api dapat dipadamkan. Api membakar bagian plafon dan benda-benda disekitarnya. Terdampak Kerusakan pada langit-langit Parkiran dan beberapa lemari. Petugas mengerahkan 1 Unit Ops Damkar. | J24: 0 | K24: 1 | L24: 0 | M24: 0 | N24: 0 | O24: 0 | P24: 0 | Q24: 0 | R24: belum diketahui | S24: 3 orang/1 unit | W24: 14 | X24: Menit
A25: 12 | B25: Sabtu, 1 Juni 2024 | C25: 22.13 Wita | D25: 22.21 s/d 23.55 Wita | H25: Karyawan Indomaret Bundaran Palam No Hp. 085249041202 | I25: Menindaklanjuti laporan telah terjadi kebakaran di Ruko sebelah Indomaret beralamat Jl. Trikora Bundaran Palam RT. 14 RW. 01 Kel. Guntung Manggis Kec. Landasan Ulin. Laporan diterima pada Pukul 22.13 Wita, petugaspun langsung menuju lokasi kebakaran. Proses pemadaman sedikit terhambat dikarenkan Rolling Door ruko tersebut terkunci. Maka petugas mengambil tindakan membobol kunci gebok tersebut. Petugas melakukan pemadaman dan akibat terdampat kebakaran yaitu beberapa dus bahan Hand Sanitizer isi ulang dan benda plastik sekitarnya. Petugas mengerahkan 1 Unit Ops Damkar. | J25: 0 | K25: 1 | L25: 0 | M25: 0 | N25: 0 | O25: 0 | P25: 0 | Q25: 0 | R25: konsleting listrik | S25: 5 orang/1 unit | W25: 15 | X25: Menit | Y25: ruko
A26: 13 | B26: Senin, 10 Juni 2024 | C26: 19.46 Wita | D26: 19.54 s/d 20.50 Wita | H26: Ibu Bibil No Hp. 087744507968 | I26: Menindaklanjuti laporan warga perihal telah terjadi kebakaran bangunan rumah yang beralamat Jl. Trikora Komp. Berlina Jaya III RT. 17 RW. 02 Blok A No. 19 Kel. Guntung Manggis Kec. Landasan Ulin. Petugas menirima laporan pada Pukul 19.46 Wita. Petugaspun langsung menuju lokasi Kebakaran. Petugas melakukan pemadaman dan pendinginan. Adapun yang terdampak 1 Buah Rumah terbakar 80% an. Bapak Sudaryanto 2 KK 7 Jiwa kerugian materil keurang lebih 80 juta rupiah. Petugas mengerahkan 1 Unit Ops Damkar. | J26: 0 | K26: 1 | L26: 0 | M26: 0 | N26: 0 | O26: 0 | P26: 2 | Q26: 7 | R26: belum diketahui | S26: 10 orang/1 unit | W26: 15 | X26: menit
A27: 14 | B27: Selasa, 23 Juli 2024 | C27: 13.47 Wita | D27: 13.57 s/d 15.00 Wita | H27: Via Grup WA Emergency Banjarbaru | I27: Menindaklanjuti laporan dari bahwa telah terjadi kebakaran bangunan (rumah) yang api masih membubuk di dalam. Laporan diterima pada Pukul 13.47 Wita Petugas langsung menuju lokasi terjadi kebakaran beralamat Komp. Sulung Residence Blok. A No. 19 RT.11 RW. 03 Kel. Landasan Ulin Tengah Kec. Liang Anggang. Api berhasil dipadamkan, terdampak peralatan rumah tangga terbakar, pemilik rumah an. Ali Yasin (disewakan), kerugian kurang lebih 10 juta rupiah, asal api masih dalam tahap penyelidikan Kepolisian. Petugas mengerahkan 1 Unit Ops Damkar Kajama Fire Truck. | J27: 0 | K27: 1 | L27: 0 | M27: 0 | N27: 0 | O27: 0 | P27: 0 | Q27: 0 | R27: belum diketahui | S27: 7 orang/1 unit | W27: 15 | X27: Menit | Y27: rumah sewaan
A28: 15 | B28: Jum`at, 9 Agustus 2024 | C28: 19.34 Wita | D28: 19.49 s/d 21.10 Wita | H28: Grup WA emergency Kota Banjarbaru | I28: Menindaklanjuti laporan tentang adanya Kebakaran Bangunan beralamat Jl. Suka Maju Komp. Citra Mandiri RT. 04 RW. 01 Kel. Landasan Ulin Utara Kec. Liang Anggang. Laporan diterima pada Pukul 19.34 Wita. Petugas melakukan persiapan dan menuju lokasi kejadian. Petugas sampai di lokasi pada Pukul 19.49 Wita. Petugas melakukan pemadaman dan pendinginan. Terdampak 2 Buah rumah terbakar 1 KK 4 Jiwa 1. Hermansyah 2. Hernawati Agustina 3. Caca 4. Hafid. Asal api masih dal penyelidikan Kepolisian. Petugas mengerahkan 1 Unit Ops Damkar Ton VII. | J28: 0 | K28: 1 | L28: 0 | M28: 0 | N28: 0 | O28: 0 | P28: 1 | Q28: 4 | R28: belum diketahui | S28: 15 orang/1 unit | W28: 15 | X28: Menit
A29: 16 | B29: Sabtu, 24 Agustus 2024 | C29: 15.09 Wita | D29: 15.20 s/d 15.50 Wita | H29: Bapak Fai No Hp. 082272701808 melalui Via Grup Emergency Kota Banjarbaru | I29: Menindaklanjuti laporan warga bahwa telah terjadi kebakaran bangunan. Laporan diterima pada pukul 15.09 Wita. Beralamat Jl. Perjuangan Komp. Pesona Fitria Mandiri RT. 08 RW. 03 Kel. sungai Tiung Kec. Cempaka. Petugas sampai di lokasi kebakaran pukul 15.20 Wita. Petugas melakukan penyemprotan dan pendinginan untuk memastikan api sudah padam. Terdampak Luas Bangunan 6 x 4 Meter yang dihuni 1 KK 4 Jiwa an. Halifah kerugian diperkirakan 20 Juta Rupiah. Asal api masih dalam penyelidikan pihak Kepolisian. Petugas mengerahkan 2 Unit Ops Damkar Kajama Tangki 3500 dan 4000. | J29: 0 | K29: 1 | L29: 0 | M29: 0 | N29: 0 | O29: 0 | P29: 1 | Q29: 4 | R29: belum diketahui | S29: 11 orang/2unit | W29: 15 | X29: Menit
A30: 17 | B30: Kamis, 29 Agustus 2024 | C30: 06.35 Wita | D30: 06.37 s/d 08.04 Wita | H30: warga No Hp. 081253189990 | I30: Menindaklanjuti laporan melaporkan bahwa telah terjadi kebakaran bangunan. Laporan diterima pada pukul 06.35 Wita. Beralamat Komp. Pesona Puri Banjar Asri Blok G No. 10 RT. 27 RW. 04 Kel. Guntung Manggis Kec. Landasan Ulin. Petugas sampai di lokasi kebakaran pukul 06.37 Wita. Petugas melakukan penyemprotan dan pendinginan untuk memastikan api sudah padam. Pemilik Rumah An.Karta Ismaya 1 KK 4 Jiwa (Alin, Maulita dan Sari). Terdampak bagian dapur rumah habis terbakar dan kerugian diperkirakan 30 Juta Rupiah. Asal api masih dalam penyelidikan pihak Kepolisian. Petugas mengerahkan 1 Unit Ops Damkar Kajama Tangki. | J30: 0 | K30: 1 | L30: 0 | M30: 0 | N30: 0 | O30: 0 | P30: 1 | Q30: 4 | R30: belum diketahui | S30: 6 orang/1 unit | W30: 15 | X30: Menit
A31: 18 | B31: Kamis, 29 Agustus 2024 | C31: 10.55 Wita | D31: 11.03 s/d 11.58 Wita | H31: Bapak Bram No Hp. 081351999528 | I31: Menindaklanjuti laporan warga perihal telah terjadi kebakaran bangunan beralamat Komp. Mustika Indah Blok 33 RT. 04 RW. 06 Kel. Guntung Manggis Kec.Landasan Ulin. Laporan awal di terima pada pukul 10.55 Wita dan petugas sampai dilokasi pada pukul 11.03 Wita. Petugas sesampai dilokasi melakukan penyemprotan dan pendinginan untuk memastikan bahwa api benar-benar padam. Pemilik Rumah an. Ibu Winarti 1 KK 1 Jiwa telah menghanguskan 1 buah rumah bagian dapur. Kerugian diperkiran kurang lebih 30 Juta Rupiah. Asal api masih dalam tahap penyelidikan Kepolisian. Petugas mengerahkan 1 Unit Ops Damkar Kajama Tangki. | J31: 0 | K31: 1 | L31: 0 | M31: 0 | N31: 0 | O31: 0 | P31: 1 | Q31: 1 | R31: belum diketahui | S31: 8 orang/2 unit | W31: 15 | X31: Menit
A32: 19 | B32: Rabu, 11 September 2024 | C32: 09.07 Wita | D32: 09.20 s/d 10.10 Wita | H32: Via Grup WA Emergency Banjarbaru an. Ahmad Rivaldi No Hp. 083105222973 | I32: Menindaklanjuti laporan perihal telah terjadi kebakaran bangunan beralamat Jl. Irigasi RT. 01 RW. 03 Kel. Mentaos Kec. Banajarbaru Utara. Terdampak 1 area kamar tidur, kasur, baju dan lemari terbakar. Dihuni 1 KK 4 Jiwa an. Yulius Bonsaeli., luas bangunan 8 x 4 M. Kerugian diperkirakan kurang lebih 1 Juta Rupiah. Asal api masih dalam tahap penyelidikan Kepolisian. Petugas mengerahkan 1 Unit Ops Damkar Kajama Tangki. | J32: 0 | K32: 1 | L32: 0 | M32: 0 | N32: 0 | O32: 0 | P32: 1 | Q32: 4 | R32: belum diketahui | S32: 7 orang/2 unit | W32: 14 | X32: Menit
A33: 20 | B33: Minggu, 15 September 2024 | C33: 06.36 Wita | D33: 06.46 s/d 07.35 Wita | H33: Via Call Center 112 an. Fahmi No Hp. 081528685710 | I33: Menindaklanjuti laporan warga perihal telah terjadi kebakaran bangunan beralamat Jl. Bhayangkara Kel. Sungai Besar Kec. Banjarbaru Selatan. Petugas melakukan penyemprotan, pendinginan dan pengecekan. Terdampak bahan pengolahan gypsum berbahan dasar karet di gudang tempat usaha an. M. Syaifullah. Kerugian kurang lebih 5 Juta Rupiah. Petugas mengerahkan 1 Unit Ops Damkar Kajama Tangki. | J33: 0 | K33: 1 | L33: 0 | M33: 0 | N33: 0 | O33: 0 | P33: 0 | Q33: 0 | R33: belum diketahui | S33: 13 orang/2 unit | W33: 14 | X33: Menit | Y33: gudang
A34: 21 | B34: Sabtu, 21 September 2024 | C34: 13.52 Wita | D34: 14.06 s/d 15.40 Wita | H34: Via Grup WA Emergency Banjarbaru | I34: Menindaklanjuti laporan warga bahwa telah terjadi kebakaran bangunan rumah beralamat Jl. Sidomulyo Raya No. 74 RT. 03 RW. 09 Kel. Landasan Ulin Timur Kec, Landasan Ulin. Terdampak 1 Buah Rumah habis terbakar + 2 Unit Sepeda motor, pemilik rumah an. Suprapto 1 KK 5 Jiwa. Kerugian di diperkirakan Ratusan Juta Rupiah. Asal api masih dalam tahap penyelidikan Kepolisian. Petugas mengerahkan 1 Unit Ops Damkar Kajama Tangki. | J34: 0 | K34: 1 | L34: 0 | M34: 0 | N34: 0 | O34: 0 | P34: 1 | Q34: 5 | R34: belum diketahui | S34: 6 orang/1 unit | W34: 14 | X34: Menit
A35: 22 | B35: Minggu, 22 September 2024 | C35: 05.09 Wita | D35: 05.16 s/d 06.40 Wita | H35: warga No Hp. 082255295234 | I35: Menindaklanjuti laporan perihal telah terjadi kebakaran bangunan Pabrik Omah Es beralamat Jl. Trans Gunung Kupang RT. 01 RW. 39 Kel. Cempaka Kec. Cempaka. Petugas langsung meluncur ke lokasi kejadian dan melakukan pemadaman, pendinginan dan pengecekan kembali memastikan api sudah padam. Terdampak Pabri Es habis terbakar, pemilik an. Kelana Jaya. petugas mengerahkan 2 Unit Ops Damkar Kajama Tangki dan Ton VII. | J35: 0 | K35: 1 | L35: 0 | M35: 0 | N35: 0 | O35: 0 | P35: 0 | Q35: 0 | R35: belum diketahui | S35: 5 orang/2 unit | W35: 14 | X35: Menit | Y35: pabrik es
A36: 23 | B36: Kamis, 10 Oktober 2024 | C36: 08.05 Wita | D36: 08.15 s/d 09.18 Wita | H36: Amalia Putri No hp. 087704273850 | I36: Menindaklanjuti laporan warga telah terjadi kebakaran bangunan beralamat Jl. Gunung Permai Barat IV RT. 38 RW. 07 Kel. Sungai Besar Kec. Banjarbaru Selatan. Petugas menerima laporan pada Pukul 08.05 Wita dan sampai di lokasi kejadian 08.15 Wita. Terdampak bangunan rumah yang terbakar gudang dan atap. Kerugian puluhan juta rupiah dan asal api kertas telur yang dibakar untuk mengusir tawon. Petugas mengerahkan 2 Unit Ops Damkar Kajama Tangki dan Ton VII. | J36: 0 | K36: 1 | L36: 0 | M36: 0 | N36: 0 | O36: 0 | P36: 1 | Q36: 3 | R36: belum diketahui | S36: 8 orang/1 unit | W36: 14 | X36: Menit
A37: 24 | B37: Rabu, 16 Oktober 2024 | C37: 09.12 Wita | D37: 09.22 s/d 10.08 Wita | H37: Grup WA Relawan Damkar | I37: Menindaklanjuti laporan telah terjadi kebakaran bangunan beralamat Jl. Trikora No. 96 RT. 06 RW. 06 Kel. Landasan Ulin Timur Kec. Landasan Ulin. Laporan diterima pada Pukul 09.12 Wita dan tiba doi lokasi 09.22 Wita. Petugas melakukan penyemprotan, pendinginan dan pengecekan ulang api benar-benar sudah padam. Terdampak pemilik an. Tiara 1 Buah Warung terbakar habis, total kerugian kurang lebih 90 Juta Rupiah. Asal api masih dalam tahap penyelidikan Kepolisian. Petugas mengerahkan 2 Unit Ops Damkar Kajama Tangki 3500 dan 4000. | J37: 0 | K37: 1 | L37: 0 | M37: 0 | N37: 0 | O37: 0 | P37: 0 | Q37: 0 | R37: belum diketahui | S37: 9 orang/2 unit | W37: 14 | X37: Menit
A38: 25 | B38: Senin, 28 Oktober 2024 | C38: 13.29 Wita | D38: 13.46 s/d 14.56 Wita | H38: Via WA Grup Emergency Banjarbaru | I38: Menindaklanjuti laporan telah terjadi kebakaran bangunan gudang Jl. A. Yani Km. 22 Jurusan Pleihari Kel. Landasan Ulin Selatan Kec. Liang Anggang. Laporan diterima pada pukul 13.29 Wita dan sampai dilokasi 13.46 Wita. Gudang PT. Fumakilla Indonesia terbakar Gudang Bahan Baku Pembuatan Obat Nyamuk kerugian kurang lebih 865 Juta Rupiah. Petugas melakukan penyemprotan, pendinginan dan pengecekan. Asal api masih dalam tahap penyelidikan Kepolisian. Petugas mengerahkan 2 Unit Ops Damkar Ton VII dan Kajama Tangki. | J38: 0 | K38: 1 | L38: 0 | M38: 0 | N38: 0 | O38: 0 | P38: 0 | Q38: 0 | R38: belum diketahui | S38: 8 orang/2 unit | W38: 15 | X38: Menit
A39: 26 | B39: Sabtu, 2 November 2024 | C39: 06.31 Wita | D39: 06.45 s/d 08.00 Wita | H39: Umu Fathum No Hp. 085821866758 | I39: Menindaklanjuti laporan warga perihal telah telah terjadi kebakaran bangunan berlamat Jl. Angkasa Kurnia III RT. 04 RW. 03 No. C4 Kel. Landasan Ulin Utara Kec. Liang Anggang. Terdampak bagian dapur rumah terbakar. Pemilik rumah an. Khairuddin 1 KK 5 Jiwa. Asal api diperkirakan dari kebocoran gas saat pemilik rumah sedang memasak. Petugas mengerahkan 1 Unit Ops Damkar Mobil Hino Kajama Tangki. | J39: 0 | K39: 1 | L39: 0 | M39: 0 | N39: 0 | O39: 0 | P39: 1 | Q39: 5 | R39: kebocoran gas | S39: 3 orang/1 unit | W39: 15 | X39: Menit
A40: 27 | B40: Sabtu, 2 November 2024 | C40: 12.27 Wita | D40: 12.37 s/d 13.15 Wita | H40: Grup WA Emergency Kota Banjarbaru | I40: Menindaklanjuti laporan bahwa telah terjadi Kebakaran Bangunan di Warung Makan Hot Plate Bdj beralamat J. STM seberang Mini Market Pinus Kel. Komet Kec. Banjarbaru Utara. Pemilik an. Afian Noor Halid terdampak terbakar bagian dapur dan tempat kasir. Api berasal dari kebocoran regulator tabung gas. Kerugian diperkirakan kurang lebih 15 Juta Rupiah. Petugas mengerahkan 1 Unit Ops Damkar Truk Hino Kajama Tangki. | J40: 0 | K40: 1 | L40: 0 | M40: 0 | N40: 0 | O40: 0 | P40: 0 | Q40: 0 | R40: kebocoran regulator gas | S40: 6 orang/2 unit | W40: 14 | X40: Menit | Y40: warung makan
A41: 28 | B41: Kamis, 7 November 2024 | C41: 11.13 Wita | D41: 11.23 s/d 12.20 Wita | H41: M. Hijrah Hasfiani No Hp. 082155641614 | I41: menindaklanjuti laporan warga perihal adanya Kebakaran Bangunan beralamat Jl. Sungai sumba RT. 39 RW. 01Kel. Guntung Manggis Kec. Landasan Ulin. Terdampak 1 buah rumah terbakar 90% + 1 Unit Sepeda Motor an. Muhammad Nasyiri 1 KK 5 Jiwa. Asal api masih dalam tahap penyelidikan Kepolisian. Petugas mengerahkan 2 Unit Ops Damkar Truk Hino Kajama Tangki. | J41: 0 | K41: 1 | L41: 0 | M41: 0 | N41: 0 | O41: 0 | P41: 1 | Q41: 5 | R41: belum diketahui | S41: 5 orang/2 unit | W41: 14 | X41: Menit
A42: 29 | B42: Rabu, 4 Desember 2024 | C42: 13.15 Wita | D42: 13.25 s/d 14.15 Wita | H42: Osmond Yaiba No Hp. 085249606121 | I42: Menindaklanjuti laporan warga perihal tentang adanya kebakaran bangunan di tempat makan Sonic Chicken beralamat Sonic Chicken RT. 13 RW. 02 Kel. Guntung Manggis Kec. Landasan Ulin. Terdampak Bagian dapur 10% terbakar dan 1 orang karyawan luka bakar 5%. Asal api dari kebocoran tabung gas. Petugas mengerahkan 1 Unit Ops Damkar Truk Hino Kajama Tangki. | J42: 0 | K42: 1 | L42: 0 | M42: 0 | N42: 0 | O42: 0 | P42: 0 | Q42: 0 | R42: kebocoran gas | S42: 11 orang/1 unit | W42: 14 | X42: Menit | Y42: restoran
A43: 30 | B43: Rabu, 18 Desember 2024 | C43: 23.35 Wita | D43: 23.44 s/d 01.25 Wita | H43: Hamid No Hp. 082157346115 | I43: Menindaklanjuti laporan warga perihal telah terjadi kebakaran bangunan beralamat Jl. Manggis RT. 04 RW. 01 Kel. Guntung Paikat Kec. Banjarbaru Selatan. Laporan diterima pada Pukul 23.35 dan tiba dilokasi pada pukul 23.44 Wita. Terdampak 3 Buah rumah terbakar 5 KK An. Abdul Hamid 4 Jiwa, Abdul Rahman 2 Jiwa, Saiful Azam 4 Jiwa, Halim Matul 2 Jiwa, Rabiatul Rumah Kosong. 1 orang mengalami luka bakar an. Zulkifli. Kerugian diperkirakan 890 Juta Rupiah. Asal api masih dalam tahap penyelidikan Kepolisian. Petugas mengerahkan 3 Unit Ops Damkar Truk Hino Ton VII, Truk Tangki Kajama 3500 Liter 2 Unit. | J43: 0 | K43: 3 | L43: 0 | M43: 0 | N43: 0 | O43: 1 | P43: 5 | Q43: 12 | R43: belum diketahui | S43: 12 orang/3 unit | W43: 14 | X43: Menit
A44: 31 | B44: Minggu, 22 Desember 2024 | C44: 23.52 Wita | D44: 00.00 s/d 01.45 Wita | H44: Call Center 112 warga an. Fajri No Hp. 087786944715 | I44: Menindaklanjuti laporan telah terjadi kebakaran bangunan tempat usaha Rumah Makan Mama Aqila beralamat Jl. Bhayangkara RT. 29 RW. 05 Kel. Sungai Besar Kec. Banjarbaru Selatan. Laporan diterima pada pukul 23.52 dan tiba di lokasi pada pukul 00.00 Wita. Akibat yang ditimbulkan terbakar 50% bangunan bagian dapur. Asal api masih dalam tahap penyelidikan kepolisian. Petugas mengerahkan 2 Unit Ops Damkar Truk Tangki Kajama 3500 dan Truk Ton VII. | J44: 0 | K44: 1 | L44: 0 | M44: 0 | N44: 0 | O44: 0 | P44: 0 | Q44: 0 | R44: belum diketahui | S44: 12 orang/2 unit | W44: 14 | X44: Menit | Y44: rumah makan
...

Sheet RESPONSE TIME (2)
B2: PEMERINTAH KOTA BANJARBARU
B3: SATUAN POLISI PAMONG PRAJA
B4: Alamat : Jl. Pangeran Antasari No. 7 Banjarbaru Kalimantan Selatan
B5: Website : Satpolpp.banjarbarukota.go.id – Email : admin@satpolpp.banjarbarukota.go.id
A7: RATA-RATA WAKTU TANGGAP (RESPONSE TIME) PENANGANAN KEBAKARAN
A8: UPT PEMADAM KEBAKARAN DAN PENYELAMATAN KOTA BANJARBARU
A9: TAHUN 2024
A12: NO | B12: HARI/TGL | C12: JAM | D12: JAM | H12: INFO VIA | I12: KEGIATAN | J12: YG TERBAKAR | L12: Hewan | M12: DLL | N12: KORBAN | P12: JUMLAH | R12: PENYEBABNYA | S12: PETUGAS/UNIT OPS | W12: RESPONSE TIME | X12: SATUAN | Y12: KET
C13: LAPORAN DITERIMA | H13: TELP/RADIO | J13: LAHAN | K13: BANGUNAN | N13: MD (org) | O13: CEDERA | P13: KK | Q13: JW | X13: JAM
A14: 1 | B14: Kamis, 1 Februari 2024 | C14: 14.20 Wita | D14: 14.28 s/d 16.10 Wita | H14: Ricky No Hp. 0819098000201 | I14: Menindaklanjuti laporan warga perihal telah terjadi kebakaran Bangunan di SDN 2 Kemuning yang beralamat di Jl. Kartini RT. 21 RW. 05 Kel. Kemuning Kec. Banjarbaru Selatan. Laporan di terima pukul 14.20 Wita petugas pun langsung bergerak ke lokasi terjadinya kebakaran. Api berhasil dipadamkan. Akibat yang ditimbulkan 4 buah Rumah Dinas Sekolah dan 1 buah gudang terbakar. 2 buah rumah rusak berat a/n. Ibu Rahmi dan Anoor. 2 buah rusak ringan dengan keadaan kosong. Asal api belum diketahui dan masih dalam penyelidikan pihak yang berwajib. Kerugian diperkirakan kurang lebih 300 Jutaan. Petugas mengerahkan 2 Unit Ops Damkar | J14: 0 | K14: 4 | L14: 0 | M14: 0 | N14: 0 | O14: 0 | P14: 1 | Q14: 1 | R14: belum diketahui | S14: 12 orang/2 unit | W14: 8 | X14: Menit
A15: 2 | B15: Kamis, 08 Februari 2024 | C15: 22.02 Wita | D15: 22.11 s/d 23.30 Wita | H15: Ibu Ida No Hp. 083836466700 | I15: Menindaklanjuti Laporan tentang adanya kebakaran bangunan di Komplek Perumahan PLN Wilayah Kalselteng Jl. Panglima Batur RT. 01 RW.06 No. A 14, 15, 16 Kel. Mentaos Kec. Banjarbaru Utara. Laporan diterima pada pukul 22.02 Wita, petugas langsung meluncur kelokasi kejadian dan dilokasi petugas melakukan pemadaman, pendinginan dan pendataan. diketahui akibat kebakaran 3 buah Rumah terbakar dengan rusak berat. 2 rumah tanpa penghuni. 1 buah rumah berpenghuni a/n. Thoha Solihin 1 KK 4 Jiwa. Kerugian bangunan kurang lebih 400 Juta Rupiah. Petugas mengerahkan 2 Unit Ops Damkar. | J15: 0 | K15: 3 | L15: 0 | M15: 0 | N15: 0 | O15: 0 | P15: 1 | Q15: 4 | R15: belum diketahui | S15: 14 orang/2 unit | W15: 13 | X15: Menit
A16: 3 | B16: Senin, 19 Februari 2024 | C16: 18.57 Wita | D16: 19.08 s/d Selesai Wita | H16: Bapak M. Subakhi No Hp. 081348107468 | I16: Menindaklanjuti laporan warga perihal telah terjadi kebakaran bangunan yang beralamat Jl. Gotong Royong Gg. Manggis RT. 16 RW. 04 Kel. Syamsudin Noor Kec. Landasan Ulin. Laporan diterima pada Pukul 18.57 Wita Petugas langsung meluncur ke lokasi kejadian. Di Lokasi petugas melakukan Pemadaman, Pendingina dan Pendataan. Terdampak kebakaran 1 Buah Rumah beserta Warung A/n. Pitrus Fatri (pemilik rumah) dihuni 1 KK 2 Jiwa. Penyebab kebakaran masih dalam penyelidikan pihak berwajib. Kerugian kurang lebih 300 juta. Petugas mengerahkan 1 Unit Ops Damkar. | J16: 0 | K16: 1 | L16: 0 | M16: 0 | N16: 0 | O16: 0 | P16: 1 | Q16: 2 | R16: belum diketahui | S16: 13 orang/1 unit | W16: 12 | X16: Menit
A17: 4 | B17: Rabu, 28 Februari 2024 | C17: 01.45Wita | D17: 02.00 s/d 03.15 Wita | H17: Via Grup WA Emergency Banjarbaru | I17: Menindaklanjuti laporan grup emergency banjarbaru bahwa telah terjadi kebakaran bangunan kandang ayam. Kondisi kandang ayam keadaan kosong baru panen uk. P : 50m L : 5m yang beralamat Jl. Sumber Makmur 1 RT. 07 RW. 04 Kel. Landasan Ulin Utara Kec. Liang Anggang. Pemilik an. Mukhtar Supian. Asal api masih dalam proses penyelidikan Kepolisian. Kondisi bangunan habis terbakar terbuat dari bahan kayu. Kerugian diperkirakan kurang lebih 50 juta rupiah. Petugas mengerahkan 2 Unit Ops Damkar | J17: 0 | K17: 1 | L17: 0 | M17: 0 | N17: 0 | O17: 0 | P17: 0 | Q17: 0 | R17: belum diketahui | S17: 11 orang/2 unit | W17: 13 | X17: Menit | Y17: kandang ayam
A18: 5 | B18: Sabtu, 16 Maret 2024 | C18: 13.07 Wita | D18: 13.16 s/d 15.50 Wita | H18: Via Grup WA Emergency Banjarbaru | I18: Menidaklanjuti laporan dari Grup Emergency Banjarbaru bahwa telah terjadi kebakaran bangunan padat penduduk beralamat Jl. Mistarcokrokusumo Kel. Cempaka Kec. Cempaka. Laporan diterima pada Pukul 13.07 Wita petugas lansung meluncur ke lokasi keajadian. Dilokasi api membesar Petugas melakukan penyemprotan mengerahkan 3 Unit Ops Damkar. Api berhasil dipadamkan dan petugas melakukan pendingian dan pendataan. Data rumah yang terdampak RT. 06 RW. 02. 1. Abdul Fatah 6 Jiwa Rusak Ringan, 2. Zainul Falihi 5 Jiwa Rusak Berat, 3. Hj. Nurul Khair Ikhrom 6 Jiwa Rusak Berat 3. Hj. Nurhayani dan Winda 5 Jiwa Rusak Berat 6. Khalifah 4 Jiwa Rusak Ringan 5. Sarniah dan M. Tarmiji 7 Jiwa Rusak Berat, Masrani 1 Jiwa Rusak Berat, 8 Raudah 1 Jiwa Rusak Sedang, 9 Musholla Rusak Sedang. Data Rumah Terdampak RT. 23 RW. 02. 1 Rabiatul Adiwiyah 4 Jiwa Rusak Berat, 2. Akhmad 7 Jiwa Rusak Berat, 3. Samlani 5 Jiwa Rusak Berat, 4. Hj. Adaniah 3 Jiwa Rusak Berat, 5. Hapsah 4 Jiwa Rusak Sedang, 6. M. Kusairi 8 Jiwa Rusak Sedang, 7. Alm. Fullah Rumah Kosong Rusak Berat, 8. Nuraini 4 Jiwa Rusak Berat. Jumlah 17 buah rumah yang terdampak dan kerugian diperkirakan kurang lebih 1 Miliyar. Asal api masih dalam proses penyelidikan Kepolisian. | J18: 0 | K18: 17 | L18: 0 | M18: 0 | N18: 0 | O18: 0 | P18: 16 | Q18: 70 | R18: belum diketahui | S18: 14 orang/2 unit | W18: 12 | X18: Menit
A19: 6 | B19: Minggu, 24 Maret 2024 | C19: 19.15 Wita | D19: 19.30 s/d 21.00 Wita | H19: Via Grup WA Emergency Banjarbaru | I19: Menindaklajuti laporan Grup WA Emergency Banjarbaru bahwa telah terjadi kebakaran bangunan di daerah golf beralamat Jl. Pelita 3 RT. 03 RW. 03 Kel. Landasan Ulin Utara Kec. Liang Anggang. Petugas menerima laporan 19.25 Wita. Petugas langsung meluncur ke lokasi kejadian. Terdampak 2 buah rumah 1. a/n. Sugeng 4 Jiwa. 2. a/n. Siti 2 Jiwa. Asal api masih dalam tahap penyelidikan kepolisian. Petugas mengerahkan 3 Unit Ops Damkar. | J19: 0 | K19: 2 | L19: 0 | M19: 0 | N19: 0 | O19: 0 | P19: 2 | Q19: 5 | R19: belum diketahui | S19: 13 orang/3 unit | W19: 15 | X19: Menit
A20: 7 | B20: Senin, 8 April 2024 | C20: 18.37 Wita | D20: 19.30 s/d 21.00 Wita | H20: via grup emergency | I20: Menindaklanjuti laporan via grup WA Emergency Banjarbaru telah terjadi kebakaran bangunan dan Laporan diterima pada pukul 23.28 Wita yang beralamat Jl. Pumpung RT. 30 RW. 10 Kel. Sungai Tiung Kec. Cempaka. Petugas menuju lokasi kejadian dan Api berhasil dipadamkan. Terdampak 2 buah rumah rusak ringan sekitar 20%. Pemilik rumah : 1. Ibu Winda Arika (Ketua RT) dan Muhammad Rijali (1 KK 2 Jiwa) 2. Ibu Jurmiah dan Dicky Irawan (1 KK 2 Jiwa) . Petugas mengerahkan 2 Unit Ops Damkar. | J20: 0 | K20: 2 | L20: 0 | M20: 0 | N20: 0 | O20: 0 | P20: 2 | Q20: 4 | R20: belum diketahui | S20: 8 orang/2 unit | W20: 7 | X20: Menit
A21: 8 | B21: Jum`at, 19 april April 2024 | C21: 18.38 Wita | D21: 18.50 s/d 19.40 Wita | H21: via grup emergency | I21: Menindaklanjuti laporan dari Grup WA Emergency Banjarbaru telah terjadi kebakaran pada pukul 18.38 Wita beralamat Jl. A. Yani Samping Radar Banjarmasin Kel. Landasan Ulin Timur Kec. Landasan Ulin. Petugas langsung menuju lokasi terdampak 1 buah lapak barang bekas ukuran 2 x 3 Meter yang terbakar. Petugas mengerahkan 1 Unit Ops damkar | J21: 0 | K21: 1 | L21: 0 | M21: 0 | N21: 0 | O21: 0 | P21: 0 | Q21: 0 | R21: belum diketahui | S21: 6 orang/1 unit | W21: 11 | X21: Menit | Y21: lapak
